Workbook

Sheet 整体测评
A1: 序号 | B1: 层面（类） | C1: 测评指标 | D1: 符合情况 | H1: 测评单元得分Si,j | I1: 指标权重Wi,j | J1: 安全层面得分情况Si | K1: 安全层面权重Wi | L1: 总分S | M1: 安全层面实际权重 | N1: 符合情况 | O1: 所占分值 | P1: 已得分值 | Q1: 丢失分值
D2: 符合 | E2: 部分符合 | F2: 不符合 | G2: 不适用
A3: 1 | B3: 物理和环境安全 | C3: 身份鉴别 | D3: =IF(VLOOKUP($C$3,'1物理和环境安全'!$A$5:$L$19,12,FALSE)=D$2,"√","") | E3: =IF(VLOOKUP($C$3,'1物理和环境安全'!$A$5:$L$19,12,FALSE)=E2,"√","") | F3: =IF(VLOOKUP($C$3,'1物理和环境安全'!$A$5:$L$19,12,FALSE)=F$2,"√","") | G3: =IF(VLOOKUP($C$3,'1物理和环境安全'!$A$5:$L$19,12,FALSE)=G$2,"√","") | H3: =VLOOKUP($C$3,'1物理和环境安全'!A:L,11,0) | I3: 1 | J3: =IF(COUNTIF(H3:H5,"N/A")=COUNTA(H3:H5),"N/A",SUMPRODUCT(H3:H5,I3:I5)/SUMIF(H3:H5,"<>N/A",I3:I5)) | K3: 10 | L3: =SUM(IF(COUNTIF(J3:J24,"=N/A")=4,0,SUMPRODUCT(J3:J24,K3:K24)/SUMIF(J3:J24,"<>N/A",K3:K24)*70),IF(COUNTIF(J25:J43,"=N/A")=4,0,SUMPRODUCT(J25:J43,K25:K43)/SUMIF(J25:J43,"<>N/A",K25:K43)*30)) | M3: =IF(J3="N/A","N/A",10*70/SUMIF(J3:J24,"<>N/A",K3:K24)) | N3: =IF(D3="√","符合",IF(E3="√","部分符合",IF(F3="√","不符合","不适用"))) | O3: =IF(H3="N/A","N/A",M$3*I3/SUMIF(H$3:H$5,"<>N/A",I$3:I$5)) | P3: =IF(H3="N/A","N/A",H3*O3) | Q3: =IF(O3="N/A","N/A",O3-P3)
A4: 2 | C4: 电子门禁记录数据存储完整性 | D4: =IF(VLOOKUP($C$4,'1物理和环境安全'!$A$5:$L$19,12,FALSE)=D$2,"√","") | E4: =IF(VLOOKUP($C$4,'1物理和环境安全'!$A$5:$L$19,12,FALSE)=E$2,"√","") | F4: =IF(VLOOKUP($C$4,'1物理和环境安全'!$A$5:$L$19,12,FALSE)=F$2,"√","") | G4: =IF(VLOOKUP($C$4,'1物理和环境安全'!$A$5:$L$19,12,FALSE)=G$2,"√","") | H4: =VLOOKUP($C$4,'1物理和环境安全'!A:L,11,0) | I4: 0.7 | N4: =IF(D4="√","符合",IF(E4="√","部分符合",IF(F4="√","不符合","不适用"))) | O4: =IF(H4="N/A","N/A",M$3*I4/SUMIF(H$3:H$5,"<>N/A",I$3:I$5)) | P4: =IF(H4="N/A","N/A",H4*O4) | Q4: =IF(O4="N/A","N/A",O4-P4)
A5: 3 | C5: 视频监控记录数据存储完整性 | D5: =IF(VLOOKUP($C$5,'1物理和环境安全'!$A$5:$L$19,12,FALSE)=D$2,"√","") | E5: =IF(VLOOKUP($C$5,'1物理和环境安全'!$A$5:$L$19,12,FALSE)=E$2,"√","") | F5: =IF(VLOOKUP($C$5,'1物理和环境安全'!$A$5:$L$19,12,FALSE)=F$2,"√","") | G5: =IF(VLOOKUP($C$5,'1物理和环境安全'!$A$5:$L$19,12,FALSE)=G$2,"√","") | H5: =VLOOKUP($C$5,'1物理和环境安全'!A:L,11,0) | I5: 0.7 | N5: =IF(D5="√","符合",IF(E5="√","部分符合",IF(F5="√","不符合","不适用"))) | O5: =IF(H5="N/A","N/A",M$3*I5/SUMIF(H$3:H$5,"<>N/A",I$3:I$5)) | P5: =IF(H5="N/A","N/A",H5*O5) | Q5: =IF(O5="N/A","N/A",O5-P5)
A6: 4 | B6: 网络和通信安全 | C6: 身份鉴别 | D6: =IF(VLOOKUP($C$6,'2网络和通信安全 '!$A$5:$L$110,12,FALSE)=D$2,"√","") | E6: =IF(VLOOKUP($C$6,'2网络和通信安全 '!$A$5:$L$110,12,FALSE)=E$2,"√","") | F6: =IF(VLOOKUP($C$6,'2网络和通信安全 '!$A$5:$L$110,12,FALSE)=F$2,"√","") | G6: =IF(VLOOKUP($C$6,'2网络和通信安全 '!$A$5:$L$110,12,FALSE)=G$2,"√","") | H6: =VLOOKUP($C$6,'2网络和通信安全 '!A:L,11,0) | I6: 1 | J6: =IF(COUNTIF(H6:H10,"N/A")=COUNTA(H6:H10),"N/A",SUMPRODUCT(H6:H10,I6:I10)/SUMIF(H6:H10,"<>N/A",I6:I10)) | K6: 20 | M6: =IF(J6="N/A","N/A",20*70/SUMIF(J3:J24,"<>N/A",K3:K24)) | N6: =IF(D6="√","符合",IF(E6="√","部分符合",IF(F6="√","不符合","不适用"))) | O6: =IF(H6="N/A","N/A",M$6*I6/SUMIF(H$6:H$10,"<>N/A",I$6:I$10)) | P6: =IF(H6="N/A","N/A",H6*O6) | Q6: =IF(O6="N/A","N/A",O6-P6)
A7: 5 | C7: 通信数据完整性 | D7: =IF(VLOOKUP($C$7,'2网络和通信安全 '!$A$5:$L$110,12,FALSE)=D$2,"√","") | E7: =IF(VLOOKUP($C$7,'2网络和通信安全 '!$A$5:$L$110,12,FALSE)=E$2,"√","") | F7: =IF(VLOOKUP($C$7,'2网络和通信安全 '!$A$5:$L$110,12,FALSE)=F$2,"√","") | G7: =IF(VLOOKUP($C$7,'2网络和通信安全 '!$A$5:$L$110,12,FALSE)=G$2,"√","") | H7: =VLOOKUP($C$7,'2网络和通信安全 '!A:L,11,0) | I7: 0.7 | N7: =IF(D7="√","符合",IF(E7="√","部分符合",IF(F7="√","不符合","不适用"))) | O7: =IF(H7="N/A","N/A",M$6*I7/SUMIF(H$6:H$10,"<>N/A",I$6:I$10)) | P7: =IF(H7="N/A","N/A",H7*O7) | Q7: =IF(O7="N/A","N/A",O7-P7)
A8: 6 | C8: 通信过程中重要数据的机密性 | D8: =IF(VLOOKUP($C$8,'2网络和通信安全 '!$A$5:$L$110,12,FALSE)=D$2,"√","") | E8: =IF(VLOOKUP($C$8,'2网络和通信安全 '!$A$5:$L$110,12,FALSE)=E$2,"√","") | F8: =IF(VLOOKUP($C$8,'2网络和通信安全 '!$A$5:$L$110,12,FALSE)=F$2,"√","") | G8: =IF(VLOOKUP($C$8,'2网络和通信安全 '!$A$5:$L$110,12,FALSE)=G$2,"√","") | H8: =VLOOKUP($C$8,'2网络和通信安全 '!A:L,11,0) | I8: 1 | N8: =IF(D8="√","符合",IF(E8="√","部分符合",IF(F8="√","不符合","不适用"))) | O8: =IF(H8="N/A","N/A",M$6*I8/SUMIF(H$6:H$10,"<>N/A",I$6:I$10)) | P8: =IF(H8="N/A","N/A",H8*O8) | Q8: =IF(O8="N/A","N/A",O8-P8)
A9: 7 | C9: 网络边界访问控制信息的完整性 | D9: =IF(VLOOKUP($C$9,'2网络和通信安全 '!$A$5:$L$110,12,FALSE)=D$2,"√","") | E9: =IF(VLOOKUP($C$9,'2网络和通信安全 '!$A$5:$L$110,12,FALSE)=E$2,"√","") | F9: =IF(VLOOKUP($C$9,'2网络和通信安全 '!$A$5:$L$110,12,FALSE)=F$2,"√","") | G9: =IF(VLOOKUP($C$9,'2网络和通信安全 '!$A$5:$L$110,12,FALSE)=G$2,"√","") | H9: =VLOOKUP($C$9,'2网络和通信安全 '!A:L,11,0) | I9: 0.4 | N9: =IF(D9="√","符合",IF(E9="√","部分符合",IF(F9="√","不符合","不适用"))) | O9: =IF(H9="N/A","N/A",M$6*I9/SUMIF(H$6:H$10,"<>N/A",I$6:I$10)) | P9: =IF(H9="N/A","N/A",H9*O9) | Q9: =IF(O9="N/A","N/A",O9-P9) | S9: 注：N/A为不适用
A10: 8 | C10: 安全接入认证 | D10: =IF(VLOOKUP($C$10,'2网络和通信安全 '!$A$5:$L$110,12,FALSE)=D$2,"√","") | E10: =IF(VLOOKUP($C$10,'2网络和通信安全 '!$A$5:$L$110,12,FALSE)=E$2,"√","") | F10: =IF(VLOOKUP($C$10,'2网络和通信安全 '!$A$5:$L$110,12,FALSE)=F$2,"√","") | G10: =IF(VLOOKUP($C$10,'2网络和通信安全 '!$A$5:$L$110,12,FALSE)=G$2,"√","") | H10: =VLOOKUP($C$10,'2网络和通信安全 '!A:L,11,0) | I10: 0.4 | N10: =IF(D10="√","符合",IF(E10="√","部分符合",IF(F10="√","不符合","不适用"))) | O10: =IF(H10="N/A","N/A",M$6*I10/SUMIF(H$6:H$10,"<>N/A",I$6:I$10)) | P10: =IF(H10="N/A","N/A",H10*O10) | Q10: =IF(O10="N/A","N/A",O10-P10)
A11: 9 | B11: 设备和计算安全 | C11: 身份鉴别 | D11: =IF(VLOOKUP($C$11,'3设备和计算安全'!$A$5:$L$58,12,FALSE)=D$2,"√","") | E11: =IF(VLOOKUP($C$11,'3设备和计算安全'!$A$5:$L$58,12,FALSE)=E$2,"√","") | F11: =IF(VLOOKUP($C$11,'3设备和计算安全'!$A$5:$L$58,12,FALSE)=F$2,"√","") | G11: =IF(VLOOKUP($C$11,'3设备和计算安全'!$A$5:$L$58,12,FALSE)=G$2,"√","") | H11: =VLOOKUP($C11,'3设备和计算安全'!A:L,11,0) | I11: 1 | J11: =IF(COUNTIF(H11:H16,"N/A")=COUNTA(H11:H16),"N/A",SUMPRODUCT(H11:H16,I11:I16)/SUMIF(H11:H16,"<>N/A",I11:I16)) | K11: 10 | M11: =IF(J11="N/A","N/A",10*70/SUMIF(J3:J24,"<>N/A",K3:K24)) | N11: =IF(D11="√","符合",IF(E11="√","部分符合",IF(F11="√","不符合","不适用"))) | O11: =IF(H11="N/A","N/A",M$11*I11/SUMIF(H$11:H$16,"<>N/A",I$11:I$16)) | P11: =IF(H11="N/A","N/A",H11*O11) | Q11: =IF(O11="N/A","N/A",O11-P11)
A12: 10 | C12: 远程管理通道安全 | D12: =IF(VLOOKUP($C$12,'3设备和计算安全'!$A$5:$L$58,12,FALSE)=D$2,"√","") | E12: =IF(VLOOKUP($C$12,'3设备和计算安全'!$A$5:$L$58,12,FALSE)=E$2,"√","") | F12: =IF(VLOOKUP($C$12,'3设备和计算安全'!$A$5:$L$58,12,FALSE)=F$2,"√","") | G12: =IF(VLOOKUP($C$12,'3设备和计算安全'!$A$5:$L$58,12,FALSE)=G$2,"√","") | H12: =VLOOKUP($C12,'3设备和计算安全'!A:L,11,0) | I12: 1 | N12: =IF(D12="√","符合",IF(E12="√","部分符合",IF(F12="√","不符合","不适用"))) | O12: =IF(H12="N/A","N/A",M$11*I12/SUMIF(H$11:H$16,"<>N/A",I$11:I$16)) | P12: =IF(H12="N/A","N/A",H12*O12) | Q12: =IF(O12="N/A","N/A",O12-P12)
A13: 11 | C13: 系统资源访问控制信息完整性 | D13: =IF(VLOOKUP($C$13,'3设备和计算安全'!$A$5:$L$58,12,FALSE)=D$2,"√","") | E13: =IF(VLOOKUP($C$13,'3设备和计算安全'!$A$5:$L$58,12,FALSE)=E$2,"√","") | F13: =IF(VLOOKUP($C$13,'3设备和计算安全'!$A$5:$L$58,12,FALSE)=F$2,"√","") | G13: =IF(VLOOKUP($C$13,'3设备和计算安全'!$A$5:$L$58,12,FALSE)=G$2,"√","") | H13: =VLOOKUP($C13,'3设备和计算安全'!A:L,11,0) | I13: 0.4 | N13: =IF(D13="√","符合",IF(E13="√","部分符合",IF(F13="√","不符合","不适用"))) | O13: =IF(H13="N/A","N/A",M$11*I13/SUMIF(H$11:H$16,"<>N/A",I$11:I$16)) | P13: =IF(H13="N/A","N/A",H13*O13) | Q13: =IF(O13="N/A","N/A",O13-P13)
A14: 12 | C14: 重要信息资源安全标记完整性 | D14: =IF(VLOOKUP($C$14,'3设备和计算安全'!$A$5:$L$58,12,FALSE)=D$2,"√","") | E14: =IF(VLOOKUP($C$14,'3设备和计算安全'!$A$5:$L$58,12,FALSE)=E$2,"√","") | F14: =IF(VLOOKUP($C$14,'3设备和计算安全'!$A$5:$L$58,12,FALSE)=F$2,"√","") | G14: =IF(VLOOKUP($C$14,'3设备和计算安全'!$A$5:$L$58,12,FALSE)=G$2,"√","") | H14: =VLOOKUP($C14,'3设备和计算安全'!A:L,11,0) | I14: 0.4 | N14: =IF(D14="√","符合",IF(E14="√","部分符合",IF(F14="√","不符合","不适用"))) | O14: =IF(H14="N/A","N/A",M$11*I14/SUMIF(H$11:H$16,"<>N/A",I$11:I$16)) | P14: =IF(H14="N/A","N/A",H14*O14) | Q14: =IF(O14="N/A","N/A",O14-P14)
A15: 13 | C15: 日志记录完整性 | D15: =IF(VLOOKUP($C$15,'3设备和计算安全'!$A$5:$L$58,12,FALSE)=D$2,"√","") | E15: =IF(VLOOKUP($C$15,'3设备和计算安全'!$A$5:$L$58,12,FALSE)=E$2,"√","") | F15: =IF(VLOOKUP($C15,'3设备和计算安全'!$A$5:$L$58,12,FALSE)=F$2,"√","") | G15: =IF(VLOOKUP($C15,'3设备和计算安全'!$A$5:$L$58,12,FALSE)=G$2,"√","") | H15: =VLOOKUP($C15,'3设备和计算安全'!A:L,11,0) | I15: 0.4 | N15: =IF(D15="√","符合",IF(E15="√","部分符合",IF(F15="√","不符合","不适用"))) | O15: =IF(H15="N/A","N/A",M$11*I15/SUMIF(H$11:H$16,"<>N/A",I$11:I$16)) | P15: =IF(H15="N/A","N/A",H15*O15) | Q15: =IF(O15="N/A","N/A",O15-P15)
A16: 14 | C16: 重要可执行程序完整性、重要可执行程序来源真实性 | D16: =IF(VLOOKUP($C$16,'3设备和计算安全'!$A$5:$L$58,12,FALSE)=D$2,"√","") | E16: =IF(VLOOKUP($C$16,'3设备和计算安全'!$A$5:$L$58,12,FALSE)=E$2,"√","") | F16: =IF(VLOOKUP($C$16,'3设备和计算安全'!$A$5:$L$58,12,FALSE)=F$2,"√","") | G16: =IF(VLOOKUP($C$16,'3设备和计算安全'!$A$5:$L$58,12,FALSE)=G$2,"√","") | H16: =VLOOKUP($C16,'3设备和计算安全'!A:L,11,0) | I16: 0.7 | N16: =IF(D16="√","符合",IF(E16="√","部分符合",IF(F16="√","不符合","不适用"))) | O16: =IF(H16="N/A","N/A",M$11*I16/SUMIF(H$11:H$16,"<>N/A",I$11:I$16)) | P16: =IF(H16="N/A","N/A",H16*O16) | Q16: =IF(O16="N/A","N/A",O16-P16)
A17: 15 | B17: 应用和数据安全 | C17: 身份鉴别 | D17: =IF(VLOOKUP($C$17,'4应用和数据安全'!$A$5:$L$111,12,FALSE)=D$2,"√","") | E17: =IF(VLOOKUP($C$17,'4应用和数据安全'!$A$5:$L$111,12,FALSE)=E$2,"√","") | F17: =IF(VLOOKUP($C$17,'4应用和数据安全'!$A$5:$L$111,12,FALSE)=F$2,"√","") | G17: =IF(VLOOKUP($C$17,'4应用和数据安全'!$A$5:$L$111,12,FALSE)=G$2,"√","") | H17: =VLOOKUP($C17,'4应用和数据安全'!A:L,11,0) | I17: 1 | J17: =IF(COUNTIF(H17:H24,"N/A")=COUNTA(H17:H24),"N/A",SUMPRODUCT(H17:H24,I17:I24)/SUMIF(H17:H24,"<>N/A",I17:I24)) | K17: 30 | M17: =IF(J17="N/A","N/A",30*70/SUMIF(J3:J24,"<>N/A",K3:K24)) | N17: =IF(D17="√","符合",IF(E17="√","部分符合",IF(F17="√","不符合","不适用"))) | O17: =IF(H17="N/A","N/A",M$17*I17/SUMIF(H$17:H$24,"<>N/A",I$17:I$24)) | P17: =IF(H17="N/A","N/A",H17*O17) | Q17: =IF(O17="N/A","N/A",O17-P17)
A18: 16 | C18: 访问控制信息完整性 | D18: =IF(VLOOKUP($C$18,'4应用和数据安全'!$A$5:$L$111,12,FALSE)=D$2,"√","") | E18: =IF(VLOOKUP($C$18,'4应用和数据安全'!$A$5:$L$111,12,FALSE)=E$2,"√","") | F18: =IF(VLOOKUP($C$18,'4应用和数据安全'!$A$5:$L$111,12,FALSE)=F$2,"√","") | G18: =IF(VLOOKUP($C$18,'4应用和数据安全'!$A$5:$L$111,12,FALSE)=G$2,"√","") | H18: =VLOOKUP($C18,'4应用和数据安全'!A:L,11,0) | I18: 0.4 | N18: =IF(D18="√","符合",IF(E18="√","部分符合",IF(F18="√","不符合","不适用"))) | O18: =IF(H18="N/A","N/A",M$17*I18/SUMIF(H$17:H$24,"<>N/A",I$17:I$24)) | P18: =IF(H18="N/A","N/A",H18*O18) | Q18: =IF(O18="N/A","N/A",O18-P18)
A19: 17 | C19: 重要信息资源安全标记完整性 | D19: =IF(VLOOKUP($C$19,'4应用和数据安全'!$A$5:$L$111,12,FALSE)=D$2,"√","") | E19: =IF(VLOOKUP($C$19,'4应用和数据安全'!$A$5:$L$111,12,FALSE)=E$2,"√","") | F19: =IF(VLOOKUP($C$19,'4应用和数据安全'!$A$5:$L$111,12,FALSE)=F$2,"√","") | G19: =IF(VLOOKUP($C$19,'4应用和数据安全'!$A$5:$L$111,12,FALSE)=G$2,"√","") | H19: =VLOOKUP($C19,'4应用和数据安全'!A:L,11,0) | I19: 0.4 | N19: =IF(D19="√","符合",IF(E19="√","部分符合",IF(F19="√","不符合","不适用"))) | O19: =IF(H19="N/A","N/A",M$17*I19/SUMIF(H$17:H$24,"<>N/A",I$17:I$24)) | P19: =IF(H19="N/A","N/A",H19*O19) | Q19: =IF(O19="N/A","N/A",O19-P19)
A20: 18 | C20: 重要数据传输机密性 | D20: =IF(VLOOKUP($C$20,'4应用和数据安全'!$A$5:$L$111,12,FALSE)=D$2,"√","") | E20: =IF(VLOOKUP($C$20,'4应用和数据安全'!$A$5:$L$111,12,FALSE)=E$2,"√","") | F20: =IF(VLOOKUP($C$20,'4应用和数据安全'!$A$5:$L$111,12,FALSE)=F$2,"√","") | G20: =IF(VLOOKUP($C$20,'4应用和数据安全'!$A$5:$L$111,12,FALSE)=G$2,"√","") | H20: =VLOOKUP($C20,'4应用和数据安全'!A:L,11,0) | I20: 1 | N20: =IF(D20="√","符合",IF(E20="√","部分符合",IF(F20="√","不符合","不适用"))) | O20: =IF(H20="N/A","N/A",M$17*I20/SUMIF(H$17:H$24,"<>N/A",I$17:I$24)) | P20: =IF(H20="N/A","N/A",H20*O20) | Q20: =IF(O20="N/A","N/A",O20-P20)
A21: 19 | C21: 重要数据存储机密性 | D21: =IF(VLOOKUP($C$21,'4应用和数据安全'!$A$5:$L$111,12,FALSE)=D$2,"√","") | E21: =IF(VLOOKUP($C$21,'4应用和数据安全'!$A$5:$L$111,12,FALSE)=E$2,"√","") | F21: =IF(VLOOKUP($C$21,'4应用和数据安全'!$A$5:$L$111,12,FALSE)=F$2,"√","") | G21: =IF(VLOOKUP($C$21,'4应用和数据安全'!$A$5:$L$111,12,FALSE)=G$2,"√","") | H21: =VLOOKUP($C21,'4应用和数据安全'!A:L,11,0) | I21: 1 | N21: =IF(D21="√","符合",IF(E21="√","部分符合",IF(F21="√","不符合","不适用"))) | O21: =IF(H21="N/A","N/A",M$17*I21/SUMIF(H$17:H$24,"<>N/A",I$17:I$24)) | P21: =IF(H21="N/A","N/A",H21*O21) | Q21: =IF(O21="N/A","N/A",O21-P21)
A22: 20 | C22: 重要数据传输完整性 | D22: =IF(VLOOKUP($C$22,'4应用和数据安全'!$A$5:$L$111,12,FALSE)=D$2,"√","") | E22: =IF(VLOOKUP($C$22,'4应用和数据安全'!$A$5:$L$111,12,FALSE)=E$2,"√","") | F22: =IF(VLOOKUP($C$22,'4应用和数据安全'!$A$5:$L$111,12,FALSE)=F$2,"√","") | G22: =IF(VLOOKUP($C$22,'4应用和数据安全'!$A$5:$L$111,12,FALSE)=G$2,"√","") | H22: =VLOOKUP($C22,'4应用和数据安全'!A:L,11,0) | I22: 0.7 | N22: =IF(D22="√","符合",IF(E22="√","部分符合",IF(F22="√","不符合","不适用"))) | O22: =IF(H22="N/A","N/A",M$17*I22/SUMIF(H$17:H$24,"<>N/A",I$17:I$24)) | P22: =IF(H22="N/A","N/A",H22*O22) | Q22: =IF(O22="N/A","N/A",O22-P22)
A23: 21 | C23: 重要数据存储完整性 | D23: =IF(VLOOKUP($C$23,'4应用和数据安全'!$A$5:$L$111,12,FALSE)=D$2,"√","") | E23: =IF(VLOOKUP($C$23,'4应用和数据安全'!$A$5:$L$111,12,FALSE)=E$2,"√","") | F23: =IF(VLOOKUP($C$23,'4应用和数据安全'!$A$5:$L$111,12,FALSE)=F$2,"√","") | G23: =IF(VLOOKUP($C$23,'4应用和数据安全'!$A$5:$L$111,12,FALSE)=G$2,"√","") | H23: =VLOOKUP($C23,'4应用和数据安全'!A:L,11,0) | I23: 0.7 | N23: =IF(D23="√","符合",IF(E23="√","部分符合",IF(F23="√","不符合","不适用"))) | O23: =IF(H23="N/A","N/A",M$17*I23/SUMIF(H$17:H$24,"<>N/A",I$17:I$24)) | P23: =IF(H23="N/A","N/A",H23*O23) | Q23: =IF(O23="N/A","N/A",O23-P23)
A24: 22 | C24: 不可否认性 | D24: =IF(VLOOKUP($C$24,'4应用和数据安全'!$A$5:$L$111,12,FALSE)=D$2,"√","") | E24: =IF(VLOOKUP($C$24,'4应用和数据安全'!$A$5:$L$111,12,FALSE)=E$2,"√","") | F24: =IF(VLOOKUP($C$24,'4应用和数据安全'!$A$5:$L$111,12,FALSE)=F$2,"√","") | G24: =IF(VLOOKUP($C$24,'4应用和数据安全'!$A$5:$L$111,12,FALSE)=G$2,"√","") | H24: =VLOOKUP($C24,'4应用和数据安全'!A:L,11,0) | I24: 1 | N24: =IF(D24="√","符合",IF(E24="√","部分符合",IF(F24="√","不符合","不适用"))) | O24: =IF(H24="N/A","N/A",M$17*I24/SUMIF(H$17:H$24,"<>N/A",I$17:I$24)) | P24: =IF(H24="N/A","N/A",H24*O24) | Q24: =IF(O24="N/A","N/A",O24-P24)
A25: 23 | B25: 管理制度 | C25: 具备密码应用安全管理制度 | D25: =IF(HLOOKUP($C25,'5管理制度'!$C$2:$H$5,4,FALSE)=D$2,"√","") | E25: =IF(HLOOKUP($C25,'5管理制度'!$C$2:$H$5,4,FALSE)=E$2,"√","") | F25: =IF(HLOOKUP($C25,'5管理制度'!$C$2:$H$5,4,FALSE)=F$2,"√","") | G25: =IF(HLOOKUP($C25,'5管理制度'!$C$2:$H$5,4,FALSE)=G$2,"√","") | H25: =HLOOKUP(C25,'5管理制度'!$C$2:$H$4,3,0) | I25: 1 | J25: =IF(COUNTIF(H25:H30,"N/A")=COUNTA(H25:H30),"N/A",SUMPRODUCT(H25:H30,I25:I30)/SUMIF(H25:H30,"<>N/A",I25:I30)) | K25: 8 | M25: =IF(J25="N/A","N/A",8*30/SUMIF(J25:J43,"<>N/A",K25:K43)) | N25: =IF(D25="√","符合",IF(E25="√","部分符合",IF(F25="√","不符合","不适用"))) | O25: =IF(H25="N/A","N/A",M$25*I25/SUMIF(H$25:H$30,"<>N/A",I$25:I$30)) | P25: =IF(H25="N/A","N/A",H25*O25) | Q25: =IF(O25="N/A","N/A",O25-P25)
A26: 24 | C26: 密钥管理规则 | D26: =IF(HLOOKUP($C26,'5管理制度'!$C$2:$H$5,4,FALSE)=D$2,"√","") | E26: =IF(HLOOKUP($C26,'5管理制度'!$C$2:$H$5,4,FALSE)=E$2,"√","") | F26: =IF(HLOOKUP($C26,'5管理制度'!$C$2:$H$5,4,FALSE)=F$2,"√","") | G26: =IF(HLOOKUP($C26,'5管理制度'!$C$2:$H$5,4,FALSE)=G$2,"√","") | H26: =HLOOKUP(C26,'5管理制度'!$C$2:$H$4,3,0) | I26: 0.7 | N26: =IF(D26="√","符合",IF(E26="√","部分符合",IF(F26="√","不符合","不适用"))) | O26: =IF(H26="N/A","N/A",M$25*I26/SUMIF(H$25:H$30,"<>N/A",I$25:I$30)) | P26: =IF(H26="N/A","N/A",H26*O26) | Q26: =IF(O26="N/A","N/A",O26-P26)
A27: 25 | C27: 建立操作规程 | D27: =IF(HLOOKUP($C27,'5管理制度'!$C$2:$H$5,4,FALSE)=D$2,"√","") | E27: =IF(HLOOKUP($C27,'5管理制度'!$C$2:$H$5,4,FALSE)=E$2,"√","") | F27: =IF(HLOOKUP($C27,'5管理制度'!$C$2:$H$5,4,FALSE)=F$2,"√","") | G27: =IF(HLOOKUP($C27,'5管理制度'!$C$2:$H$5,4,FALSE)=G$2,"√","") | H27: =HLOOKUP(C27,'5管理制度'!$C$2:$H$4,3,0) | I27: 0.7 | N27: =IF(D27="√","符合",IF(E27="√","部分符合",IF(F27="√","不符合","不适用"))) | O27: =IF(H27="N/A","N/A",M$25*I27/SUMIF(H$25:H$30,"<>N/A",I$25:I$30)) | P27: =IF(H27="N/A","N/A",H27*O27) | Q27: =IF(O27="N/A","N/A",O27-P27)
A28: 26 | C28: 定期修订安全管理制度 | D28: =IF(HLOOKUP($C28,'5管理制度'!$C$2:$H$5,4,FALSE)=D$2,"√","") | E28: =IF(HLOOKUP($C28,'5管理制度'!$C$2:$H$5,4,FALSE)=E$2,"√","") | F28: =IF(HLOOKUP($C28,'5管理制度'!$C$2:$H$5,4,FALSE)=F$2,"√","") | G28: =IF(HLOOKUP($C28,'5管理制度'!$C$2:$H$5,4,FALSE)=G$2,"√","") | H28: =HLOOKUP(C28,'5管理制度'!$C$2:$H$4,3,0) | I28: 0.7 | N28: =IF(D28="√","符合",IF(E28="√","部分符合",IF(F28="√","不符合","不适用"))) | O28: =IF(H28="N/A","N/A",M$25*I28/SUMIF(H$25:H$30,"<>N/A",I$25:I$30)) | P28: =IF(H28="N/A","N/A",H28*O28) | Q28: =IF(O28="N/A","N/A",O28-P28)
A29: 27 | C29: 明确管理制度发布流程 | D29: =IF(HLOOKUP($C29,'5管理制度'!$C$2:$H$5,4,FALSE)=D$2,"√","") | E29: =IF(HLOOKUP($C29,'5管理制度'!$C$2:$H$5,4,FALSE)=E$2,"√","") | F29: =IF(HLOOKUP($C29,'5管理制度'!$C$2:$H$5,4,FALSE)=F$2,"√","") | G29: =IF(HLOOKUP($C29,'5管理制度'!$C$2:$H$5,4,FALSE)=G$2,"√","") | H29: =HLOOKUP(C29,'5管理制度'!$C$2:$H$4,3,0) | I29: 0.7 | N29: =IF(D29="√","符合",IF(E29="√","部分符合",IF(F29="√","不符合","不适用"))) | O29: =IF(H29="N/A","N/A",M$25*I29/SUMIF(H$25:H$30,"<>N/A",I$25:I$30)) | P29: =IF(H29="N/A","N/A",H29*O29) | Q29: =IF(O29="N/A","N/A",O29-P29)
A30: 28 | C30: 制度执行过程记录留存 | D30: =IF(HLOOKUP($C30,'5管理制度'!$C$2:$H$5,4,FALSE)=D$2,"√","") | E30: =IF(HLOOKUP($C30,'5管理制度'!$C$2:$H$5,4,FALSE)=E$2,"√","") | F30: =IF(HLOOKUP($C30,'5管理制度'!$C$2:$H$5,4,FALSE)=F$2,"√","") | G30: =IF(HLOOKUP($C30,'5管理制度'!$C$2:$H$5,4,FALSE)=G$2,"√","") | H30: =HLOOKUP(C30,'5管理制度'!$C$2:$H$4,3,0) | I30: 0.7 | N30: =IF(D30="√","符合",IF(E30="√","部分符合",IF(F30="√","不符合","不适用"))) | O30: =IF(H30="N/A","N/A",M$25*I30/SUMIF(H$25:H$30,"<>N/A",I$25:I$30)) | P30: =IF(H30="N/A","N/A",H30*O30) | Q30: =IF(O30="N/A","N/A",O30-P30)
A31: 29 | B31: 人员管理 | C31: 了解并遵守密码相关法律法规和密码管理制度 | D31: =IF(HLOOKUP($C31,'6人员管理'!$C$2:$G$5,4,FALSE)=D$2,"√","") | E31: =IF(HLOOKUP($C31,'6人员管理'!$C$2:$G$5,4,FALSE)=E$2,"√","") | F31: =IF(HLOOKUP($C31,'6人员管理'!$C$2:$G$5,4,FALSE)=F$2,"√","") | G31: =IF(HLOOKUP($C31,'6人员管理'!$C$2:$G$5,4,FALSE)=G$2,"√","") | H31: =HLOOKUP(C31,'6人员管理'!$C$2:$G$4,3,0) | I31: 0.7 | J31: =IF(COUNTIF(H31:H35,"N/A")=COUNTA(H31:H35),"N/A",SUMPRODUCT(H31:H35,I31:I35)/SUMIF(H31:H35,"<>N/A",I31:I35)) | K31: 8 | M31: =IF(J31="N/A","N/A",8*30/SUMIF(J25:J43,"<>N/A",K25:K43)) | N31: =IF(D31="√","符合",IF(E31="√","部分符合",IF(F31="√","不符合","不适用"))) | O31: =IF(H31="N/A","N/A",M$31*I31/SUMIF(H$31:H$35,"<>N/A",I$31:I$35)) | P31: =IF(H31="N/A","N/A",H31*O31) | Q31: =IF(O31="N/A","N/A",O31-P31)
A32: 30 | C32: 建立密码应用岗位责任制度 | D32: =IF(HLOOKUP($C32,'6人员管理'!$C$2:$G$5,4,FALSE)=D$2,"√","") | E32: =IF(HLOOKUP($C32,'6人员管理'!$C$2:$G$5,4,FALSE)=E$2,"√","") | F32: =IF(HLOOKUP($C32,'6人员管理'!$C$2:$G$5,4,FALSE)=F$2,"√","") | G32: =IF(HLOOKUP($C32,'6人员管理'!$C$2:$G$5,4,FALSE)=G$2,"√","") | H32: =HLOOKUP(C32,'6人员管理'!$C$2:$G$4,3,0) | I32: 1 | N32: =IF(D32="√","符合",IF(E32="√","部分符合",IF(F32="√","不符合","不适用"))) | O32: =IF(H32="N/A","N/A",M$31*I32/SUMIF(H$31:H$35,"<>N/A",I$31:I$35)) | P32: =IF(H32="N/A","N/A",H32*O32) | Q32: =IF(O32="N/A","N/A",O32-P32)
A33: 31 | C33: 建立上岗人员培训制度 | D33: =IF(HLOOKUP($C33,'6人员管理'!$C$2:$G$5,4,FALSE)=D$2,"√","") | E33: =IF(HLOOKUP($C33,'6人员管理'!$C$2:$G$5,4,FALSE)=E$2,"√","") | F33: =IF(HLOOKUP($C33,'6人员管理'!$C$2:$G$5,4,FALSE)=F$2,"√","") | G33: =IF(HLOOKUP($C33,'6人员管理'!$C$2:$G$5,4,FALSE)=G$2,"√","") | H33: =HLOOKUP(C33,'6人员管理'!$C$2:$G$4,3,0) | I33: 0.7 | N33: =IF(D33="√","符合",IF(E33="√","部分符合",IF(F33="√","不符合","不适用"))) | O33: =IF(H33="N/A","N/A",M$31*I33/SUMIF(H$31:H$35,"<>N/A",I$31:I$35)) | P33: =IF(H33="N/A","N/A",H33*O33) | Q33: =IF(O33="N/A","N/A",O33-P33)
A34: 32 | C34: 定期进行安全岗位人员考核 | D34: =IF(HLOOKUP($C34,'6人员管理'!$C$2:$G$5,4,FALSE)=D$2,"√","") | E34: =IF(HLOOKUP($C34,'6人员管理'!$C$2:$G$5,4,FALSE)=E$2,"√","") | F34: =IF(HLOOKUP($C34,'6人员管理'!$C$2:$G$5,4,FALSE)=F$2,"√","") | G34: =IF(HLOOKUP($C34,'6人员管理'!$C$2:$G$5,4,FALSE)=G$2,"√","") | H34: =HLOOKUP(C34,'6人员管理'!$C$2:$G$4,3,0) | I34: 0.7 | N34: =IF(D34="√","符合",IF(E34="√","部分符合",IF(F34="√","不符合","不适用"))) | O34: =IF(H34="N/A","N/A",M$31*I34/SUMIF(H$31:H$35,"<>N/A",I$31:I$35)) | P34: =IF(H34="N/A","N/A",H34*O34) | Q34: =IF(O34="N/A","N/A",O34-P34)
A35: 33 | C35: 建立关键岗位人员保密制度和调离制度 | D35: =IF(HLOOKUP($C35,'6人员管理'!$C$2:$G$5,4,FALSE)=D$2,"√","") | E35: =IF(HLOOKUP($C35,'6人员管理'!$C$2:$G$5,4,FALSE)=E$2,"√","") | F35: =IF(HLOOKUP($C35,'6人员管理'!$C$2:$G$5,4,FALSE)=F$2,"√","") | G35: =IF(HLOOKUP($C35,'6人员管理'!$C$2:$G$5,4,FALSE)=G$2,"√","") | H35: =HLOOKUP(C35,'6人员管理'!$C$2:$G$4,3,0) | I35: 0.7 | N35: =IF(D35="√","符合",IF(E35="√","部分符合",IF(F35="√","不符合","不适用"))) | O35: =IF(H35="N/A","N/A",M$31*I35/SUMIF(H$31:H$35,"<>N/A",I$31:I$35)) | P35: =IF(H35="N/A","N/A",H35*O35) | Q35: =IF(O35="N/A","N/A",O35-P35)
A36: 34 | B36: 建设运行 | C36: 制定密码应用方案 | D36: =IF(HLOOKUP($C36,'7建设运行'!$C$2:$G$5,4,FALSE)=D$2,"√","") | E36: =IF(HLOOKUP($C36,'7建设运行'!$C$2:$G$5,4,FALSE)=E$2,"√","") | F36: =IF(HLOOKUP($C36,'7建设运行'!$C$2:$G$5,4,FALSE)=F$2,"√","") | G36: =IF(HLOOKUP($C36,'7建设运行'!$C$2:$G$5,4,FALSE)=G$2,"√","") | H36: =HLOOKUP(C36,'7建设运行'!$C$2:$G$4,3,0) | I36: 1 | J36: =IF(COUNTIF(H36:H40,"N/A")=COUNTA(H36:H40),"N/A",SUMPRODUCT(H36:H40,I36:I40)/SUMIF(H36:H40,"<>N/A",I36:I40)) | K36: 8 | M36: =IF(J36="N/A","N/A",8*30/SUMIF(J25:J43,"<>N/A",K25:K43)) | N36: =IF(D36="√","符合",IF(E36="√","部分符合",IF(F36="√","不符合","不适用"))) | O36: =IF(H36="N/A","N/A",M$36*I36/SUMIF(H$36:H$40,"<>N/A",I$36:I$40)) | P36: =IF(H36="N/A","N/A",H36*O36) | Q36: =IF(O36="N/A","N/A",O36-P36)
A37: 35 | C37: 制定密钥安全管理策略 | D37: =IF(HLOOKUP($C37,'7建设运行'!$C$2:$G$5,4,FALSE)=D$2,"√","") | E37: =IF(HLOOKUP($C37,'7建设运行'!$C$2:$G$5,4,FALSE)=E$2,"√","") | F37: =IF(HLOOKUP($C37,'7建设运行'!$C$2:$G$5,4,FALSE)=F$2,"√","") | G37: =IF(HLOOKUP($C37,'7建设运行'!$C$2:$G$5,4,FALSE)=G$2,"√","") | H37: =HLOOKUP(C37,'7建设运行'!$C$2:$G$4,3,0) | I37: 1 | N37: =IF(D37="√","符合",IF(E37="√","部分符合",IF(F37="√","不符合","不适用"))) | O37: =IF(H37="N/A","N/A",M$36*I37/SUMIF(H$36:H$40,"<>N/A",I$36:I$40)) | P37: =IF(H37="N/A","N/A",H37*O37) | Q37: =IF(O37="N/A","N/A",O37-P37)
A38: 36 | C38: 制定实施方案 | D38: =IF(HLOOKUP($C38,'7建设运行'!$C$2:$G$5,4,FALSE)=D$2,"√","") | E38: =IF(HLOOKUP($C38,'7建设运行'!$C$2:$G$5,4,FALSE)=E$2,"√","") | F38: =IF(HLOOKUP($C38,'7建设运行'!$C$2:$G$5,4,FALSE)=F$2,"√","") | G38: =IF(HLOOKUP($C38,'7建设运行'!$C$2:$G$5,4,FALSE)=G$2,"√","") | H38: =HLOOKUP(C38,'7建设运行'!$C$2:$G$4,3,0) | I38: 0.7 | N38: =IF(D38="√","符合",IF(E38="√","部分符合",IF(F38="√","不符合","不适用"))) | O38: =IF(H38="N/A","N/A",M$36*I38/SUMIF(H$36:H$40,"<>N/A",I$36:I$40)) | P38: =IF(H38="N/A","N/A",H38*O38) | Q38: =IF(O38="N/A","N/A",O38-P38)
A39: 37 | C39: 投入运行前进行密码应用安全性评估 | D39: =IF(HLOOKUP($C39,'7建设运行'!$C$2:$G$5,4,FALSE)=D$2,"√","") | E39: =IF(HLOOKUP($C39,'7建设运行'!$C$2:$G$5,4,FALSE)=E$2,"√","") | F39: =IF(HLOOKUP($C39,'7建设运行'!$C$2:$G$5,4,FALSE)=F$2,"√","") | G39: =IF(HLOOKUP($C39,'7建设运行'!$C$2:$G$5,4,FALSE)=G$2,"√","") | H39: =HLOOKUP(C39,'7建设运行'!$C$2:$G$4,3,0) | I39: 1 | N39: =IF(D39="√","符合",IF(E39="√","部分符合",IF(F39="√","不符合","不适用"))) | O39: =IF(H39="N/A","N/A",M$36*I39/SUMIF(H$36:H$40,"<>N/A",I$36:I$40)) | P39: =IF(H39="N/A","N/A",H39*O39) | Q39: =IF(O39="N/A","N/A",O39-P39)
A40: 38 | C40: 定期开展密码应用安全性评估及攻防对抗演习 | D40: =IF(HLOOKUP($C40,'7建设运行'!$C$2:$G$5,4,FALSE)=D$2,"√","") | E40: =IF(HLOOKUP($C40,'7建设运行'!$C$2:$G$5,4,FALSE)=E$2,"√","") | F40: =IF(HLOOKUP($C40,'7建设运行'!$C$2:$G$5,4,FALSE)=F$2,"√","") | G40: =IF(HLOOKUP($C40,'7建设运行'!$C$2:$G$5,4,FALSE)=G$2,"√","") | H40: =HLOOKUP(C40,'7建设运行'!$C$2:$G$4,3,0) | I40: 0.7 | N40: =IF(D40="√","符合",IF(E40="√","部分符合",IF(F40="√","不符合","不适用"))) | O40: =IF(H40="N/A","N/A",M$36*I40/SUMIF(H$36:H$40,"<>N/A",I$36:I$40)) | P40: =IF(H40="N/A","N/A",H40*O40) | Q40: =IF(O40="N/A","N/A",O40-P40)
...

Sheet 说明
O4: 安全强度低于 112 比特的密码算法为弱算法
O5: 非对称算法 | P5: 算法强度 | R5: 对称算法 | S5: 算法强度 | U5: 杂凑算法 | V5: 算法强度
O6: RSA-1024 | P6: 80 | R6: DES | S6: 56 | U6: MD5 | V6: /
O7: RSA-2048 | P7: 112 | R7: 2TDEA | S7: 80-112 | U7: SHA1 | V7: 60
O8: RSA-3072 | P8: 128 | R8: 3TDEA | S8: 112（2023年后不再推荐使用） | U8: SHA224 | V8: 112
O9: ECC-112 | P9: 56 | R9: AES128 | S9: 128 | U9: SHA256 | V9: 128
O10: ECC-160 | P10: 80 | R10: AES192 | S10: 192 | U10: SHA384 | V10: 192
O11: ECC-224 | P11: 112 | R11: AES256 | S11: 256 | U11: SHA512 | V11: 256
O12: ECC-256 | P12: 128 | R12: SM4 | S12: 128 | U12: SM3 | V12: 128
O13: SM2 | P13: 128 | R13: ZUC | S13: 128

Sheet 1物理和环境安全
A1: 物理和环境安全
A3: 测评单元 | B3: 测评对象 | C3: 适用情况 | D3: 涉及情况 | J3: 符合情况 | K3: 测评单元得分 S i, j | L3: 单元测评结果 | M3: 有效对象数量 | N3: 所占分值 | O3: 已得分值 | P3: 丢失分值
D4: 密码使用有效性D | E4: 密码算法/技术 合规性A | F4: 密钥管理安全K | G4: Ra | H4: Rk | I4: 得分
A5: 身份鉴别 | B5: 建行宁夏分行租赁机房 | C5: 适用 | D5: √ | E5: √ | F5: √ | G5: 1 | H5: 1 | I5: =IF(C5="不适用","N/A",IF(D5<>"√",0,IF((E5="√")*AND(F5="√"),1,IF((E5<>"√")*AND(F5="√"),0.5*G5,IF((E5="√")*AND(F5<>"√"),0.5*H5,IF((E5<>"√")*AND(F5<>"√"),0.25*G5*H5)))))) | J5: =IF(I5="N/A","不适用",IF(I5=1,"符合",IF(I5=0,"不符合","部分符合"))) | K5: =IF(COUNTIF($I5:$I9,"N/A")=COUNTA($I5:$I9),"N/A",AVERAGE($I5:$I9)) | L5: =IF(K5="N/A","不适用",IF(K5=1,"符合",IF(K5=0,"不符合","部分符合"))) | M5: =(COUNTA($C5:$C9)-COUNTIF($C5:$C9,"不适用")) | N5: =IF(I5="N/A","N/A",整体测评!O$3/M$5) | O5: =IF(I5="N/A","N/A",I5*N5) | P5: =IF(I5="N/A","N/A",N5-O5)
B6: 建行云平台-武汉数据中心机房 | C6: 适用 | D6: √ | E6: √ | F6: × | G6: 1 | H6: 1 | I6: =IF(C6="不适用","N/A",IF(D6<>"√",0,IF((E6="√")*AND(F6="√"),1,IF((E6<>"√")*AND(F6="√"),0.5*G6,IF((E6="√")*AND(F6<>"√"),0.5*H6,IF((E6<>"√")*AND(F6<>"√"),0.25*G6*H6)))))) | J6: =IF(I6="N/A","不适用",IF(I6=1,"符合",IF(I6=0,"不符合","部分符合"))) | N6: =IF(I6="N/A","N/A",整体测评!O$3/M$5) | O6: =IF(I6="N/A","N/A",I6*N6) | P6: =IF(I6="N/A","N/A",N6-O6)
B7: 建行云平台-洋桥数据中心机房 | C7: 适用 | D7: √ | E7: √ | F7: × | G7: 1 | H7: 1 | I7: =IF(C7="不适用","N/A",IF(D7<>"√",0,IF((E7="√")*AND(F7="√"),1,IF((E7<>"√")*AND(F7="√"),0.5*G7,IF((E7="√")*AND(F7<>"√"),0.5*H7,IF((E7<>"√")*AND(F7<>"√"),0.25*G7*H7)))))) | J7: =IF(I7="N/A","不适用",IF(I7=1,"符合",IF(I7=0,"不符合","部分符合"))) | N7: =IF(I7="N/A","N/A",整体测评!O$3/M$5) | O7: =IF(I7="N/A","N/A",I7*N7) | P7: =IF(I7="N/A","N/A",N7-O7)
B8: 建行云平台-稻香湖数据中心机房 | C8: 适用 | D8: √ | E8: √ | F8: × | G8: 1 | H8: 1 | I8: =IF(C8="不适用","N/A",IF(D8<>"√",0,IF((E8="√")*AND(F8="√"),1,IF((E8<>"√")*AND(F8="√"),0.5*G8,IF((E8="√")*AND(F8<>"√"),0.5*H8,IF((E8<>"√")*AND(F8<>"√"),0.25*G8*H8)))))) | J8: =IF(I8="N/A","不适用",IF(I8=1,"符合",IF(I8=0,"不符合","部分符合"))) | N8: =IF(I8="N/A","N/A",整体测评!O$3/M$5) | O8: =IF(I8="N/A","N/A",I8*N8) | P8: =IF(I8="N/A","N/A",N8-O8)
B9: 勿删 | C9: 不适用 | D9: × | G9: 1 | H9: 1 | I9: =IF(C9="不适用","N/A",IF(D9<>"√",0,IF((E9="√")*AND(F9="√"),1,IF((E9<>"√")*AND(F9="√"),0.5*G9,IF((E9="√")*AND(F9<>"√"),0.5*H9,IF((E9<>"√")*AND(F9<>"√"),0.25*G9*H9)))))) | J9: =IF(I9="N/A","不适用",IF(I9=1,"符合",IF(I9=0,"不符合","部分符合"))) | N9: =IF(I9="N/A","N/A",整体测评!O$3/M$5) | O9: =IF(I9="N/A","N/A",I9*N9) | P9: =IF(I9="N/A","N/A",N9-O9)
A10: 电子门禁记录数据存储完整性 | B10: 建行宁夏分行租赁机房 | C10: 适用 | D10: √ | E10: √ | F10: √ | G10: 1 | H10: 1 | I10: =IF(C10="不适用","N/A",IF(D10<>"√",0,IF((E10="√")*AND(F10="√"),1,IF((E10<>"√")*AND(F10="√"),0.5*G10,IF((E10="√")*AND(F10<>"√"),0.5*H10,IF((E10<>"√")*AND(F10<>"√"),0.25*G10*H10)))))) | J10: =IF(I10="N/A","不适用",IF(I10=1,"符合",IF(I10=0,"不符合","部分符合"))) | K10: =IF(COUNTIF($I10:$I14,"N/A")=COUNTA($I10:$I14),"N/A",AVERAGE($I10:$I14)) | L10: =IF(K10="N/A","不适用",IF(K10=1,"符合",IF(K10=0,"不符合","部分符合"))) | M10: =(COUNTA($C10:$C14)-COUNTIF($C10:$C14,"不适用")) | N10: =IF(I10="N/A","N/A",整体测评!O$4/M$10) | O10: =IF(I10="N/A","N/A",I10*N10) | P10: =IF(I10="N/A","N/A",N10-O10)
B11: 建行云平台-武汉数据中心机房 | C11: 适用 | D11: × | E11: × | F11: × | G11: 1 | H11: 1 | I11: =IF(C11="不适用","N/A",IF(D11<>"√",0,IF((E11="√")*AND(F11="√"),1,IF((E11<>"√")*AND(F11="√"),0.5*G11,IF((E11="√")*AND(F11<>"√"),0.5*H11,IF((E11<>"√")*AND(F11<>"√"),0.25*G11*H11)))))) | J11: =IF(I11="N/A","不适用",IF(I11=1,"符合",IF(I11=0,"不符合","部分符合"))) | N11: =IF(I11="N/A","N/A",整体测评!O$4/M$10) | O11: =IF(I11="N/A","N/A",I11*N11) | P11: =IF(I11="N/A","N/A",N11-O11)
B12: 建行云平台-洋桥数据中心机房 | C12: 适用 | D12: × | E12: × | F12: × | G12: 1 | H12: 1 | I12: =IF(C12="不适用","N/A",IF(D12<>"√",0,IF((E12="√")*AND(F12="√"),1,IF((E12<>"√")*AND(F12="√"),0.5*G12,IF((E12="√")*AND(F12<>"√"),0.5*H12,IF((E12<>"√")*AND(F12<>"√"),0.25*G12*H12)))))) | J12: =IF(I12="N/A","不适用",IF(I12=1,"符合",IF(I12=0,"不符合","部分符合"))) | N12: =IF(I12="N/A","N/A",整体测评!O$4/M$10) | O12: =IF(I12="N/A","N/A",I12*N12) | P12: =IF(I12="N/A","N/A",N12-O12)
B13: 建行云平台-稻香湖数据中心机房 | C13: 适用 | D13: × | E13: × | F13: × | G13: 1 | H13: 1 | I13: =IF(C13="不适用","N/A",IF(D13<>"√",0,IF((E13="√")*AND(F13="√"),1,IF((E13<>"√")*AND(F13="√"),0.5*G13,IF((E13="√")*AND(F13<>"√"),0.5*H13,IF((E13<>"√")*AND(F13<>"√"),0.25*G13*H13)))))) | J13: =IF(I13="N/A","不适用",IF(I13=1,"符合",IF(I13=0,"不符合","部分符合"))) | N13: =IF(I13="N/A","N/A",整体测评!O$4/M$10) | O13: =IF(I13="N/A","N/A",I13*N13) | P13: =IF(I13="N/A","N/A",N13-O13)
B14: 勿删 | C14: 不适用 | D14: × | G14: 1 | H14: 1 | I14: =IF(C14="不适用","N/A",IF(D14<>"√",0,IF((E14="√")*AND(F14="√"),1,IF((E14<>"√")*AND(F14="√"),0.5*G14,IF((E14="√")*AND(F14<>"√"),0.5*H14,IF((E14<>"√")*AND(F14<>"√"),0.25*G14*H14)))))) | J14: =IF(I14="N/A","不适用",IF(I14=1,"符合",IF(I14=0,"不符合","部分符合"))) | N14: =IF(I14="N/A","N/A",整体测评!O$4/M$10) | O14: =IF(I14="N/A","N/A",I14*N14) | P14: =IF(I14="N/A","N/A",N14-O14)
A15: 视频监控记录数据存储完整性 | B15: 建行宁夏分行租赁机房 | C15: 适用 | D15: √ | E15: √ | F15: √ | G15: 1 | H15: 1 | I15: =IF(C15="不适用","N/A",IF(D15<>"√",0,IF((E15="√")*AND(F15="√"),1,IF((E15<>"√")*AND(F15="√"),0.5*G15,IF((E15="√")*AND(F15<>"√"),0.5*H15,IF((E15<>"√")*AND(F15<>"√"),0.25*G15*H15)))))) | J15: =IF(I15="N/A","不适用",IF(I15=1,"符合",IF(I15=0,"不符合","部分符合"))) | K15: =IF(COUNTIF($I15:$I19,"N/A")=COUNTA($I15:$I19),"N/A",AVERAGE($I15:$I19)) | L15: =IF(K15="N/A","不适用",IF(K15=1,"符合",IF(K15=0,"不符合","部分符合"))) | M15: =(COUNTA($C15:$C19)-COUNTIF($C15:$C19,"不适用")) | N15: =IF(I15="N/A","N/A",整体测评!O$5/M$15) | O15: =IF(I15="N/A","N/A",I15*N15) | P15: =IF(I15="N/A","N/A",N15-O15)
B16: 建行云平台-武汉数据中心机房 | C16: 适用 | D16: × | E16: × | F16: × | G16: 1 | H16: 1 | I16: =IF(C16="不适用","N/A",IF(D16<>"√",0,IF((E16="√")*AND(F16="√"),1,IF((E16<>"√")*AND(F16="√"),0.5*G16,IF((E16="√")*AND(F16<>"√"),0.5*H16,IF((E16<>"√")*AND(F16<>"√"),0.25*G16*H16)))))) | J16: =IF(I16="N/A","不适用",IF(I16=1,"符合",IF(I16=0,"不符合","部分符合"))) | N16: =IF(I16="N/A","N/A",整体测评!O$5/M$15) | O16: =IF(I16="N/A","N/A",I16*N16) | P16: =IF(I16="N/A","N/A",N16-O16)
B17: 建行云平台-洋桥数据中心机房 | C17: 适用 | D17: × | E17: × | F17: × | G17: 1 | H17: 1 | I17: =IF(C17="不适用","N/A",IF(D17<>"√",0,IF((E17="√")*AND(F17="√"),1,IF((E17<>"√")*AND(F17="√"),0.5*G17,IF((E17="√")*AND(F17<>"√"),0.5*H17,IF((E17<>"√")*AND(F17<>"√"),0.25*G17*H17)))))) | J17: =IF(I17="N/A","不适用",IF(I17=1,"符合",IF(I17=0,"不符合","部分符合"))) | N17: =IF(I17="N/A","N/A",整体测评!O$5/M$15) | O17: =IF(I17="N/A","N/A",I17*N17) | P17: =IF(I17="N/A","N/A",N17-O17)
B18: 建行云平台-稻香湖数据中心机房 | C18: 适用 | D18: × | E18: × | F18: × | G18: 1 | H18: 1 | I18: =IF(C18="不适用","N/A",IF(D18<>"√",0,IF((E18="√")*AND(F18="√"),1,IF((E18<>"√")*AND(F18="√"),0.5*G18,IF((E18="√")*AND(F18<>"√"),0.5*H18,IF((E18<>"√")*AND(F18<>"√"),0.25*G18*H18)))))) | J18: =IF(I18="N/A","不适用",IF(I18=1,"符合",IF(I18=0,"不符合","部分符合"))) | N18: =IF(I18="N/A","N/A",整体测评!O$5/M$15) | O18: =IF(I18="N/A","N/A",I18*N18) | P18: =IF(I18="N/A","N/A",N18-O18)
B19: 勿删 | C19: 不适用 | D19: × | G19: 1 | H19: 1 | I19: =IF(C19="不适用","N/A",IF(D19<>"√",0,IF((E19="√")*AND(F19="√"),1,IF((E19<>"√")*AND(F19="√"),0.5*G19,IF((E19="√")*AND(F19<>"√"),0.5*H19,IF((E19<>"√")*AND(F19<>"√"),0.25*G19*H19)))))) | J19: =IF(I19="N/A","不适用",IF(I19=1,"符合",IF(I19=0,"不符合","部分符合"))) | N19: =IF(I19="N/A","N/A",整体测评!O$5/M$15) | O19: =IF(I19="N/A","N/A",I19*N19) | P19: =IF(I19="N/A","N/A",N19-O19)

Sheet 2网络和通信安全
A1: 网络和通信安全
A3: 测评单元 | B3: 测评对象 | C3: 适用情况 | D3: 涉及情况 | I3: 分值 Si,j,k | J3: 符合情况 | K3: 测评单元得分 S i, j | L3: 单元测评结果 | M3: 有效对象数量 | N3: 所占分值 | O3: 已得分值 | P3: 丢失分值
D4: 密码使用有效性D | E4: 密码算法/技术 合规性A | F4: 密钥管理安全K | G4: Ra | H4: Rk
A5: 身份鉴别 | B5: 智慧缴费系统小程序通道 | C5: 适用 | D5: √ | E5: × | F5: × | G5: 1 | H5: 1 | I5: =IF(C5="不适用","N/A",IF(D5<>"√",0,IF((E5="√")*AND(F5="√"),1,IF((E5<>"√")*AND(F5="√"),0.5*G5,IF((E5="√")*AND(F5<>"√"),0.5*H5,IF((E5<>"√")*AND(F5<>"√"),0.25*G5*H5)))))) | J5: =IF(I5="N/A","不适用",IF(I5=1,"符合",IF(I5=0,"不符合","部分符合"))) | K5: =IF(COUNTIF($I5:$I38,"N/A")=COUNTA($I5:$I38),"N/A",AVERAGE($I5:$I38)) | L5: =IF(K5="N/A","不适用",IF(K5=1,"符合",IF(K5=0,"不符合","部分符合"))) | M5: =(COUNTA($C5:$C38)-COUNTIF($C5:$C38,"不适用")) | N5: =IF(I5="N/A","N/A",整体测评!O$6/M$5) | O5: =IF(I5="N/A","N/A",I5*N5) | P5: =IF(I5="N/A","N/A",N5-O5) | Q5: 注：N/A为不适用
B6: 智慧缴费系统与吴忠供热之间的通道 | C6: 适用 | D6: × | E6: / | F6: / | G6: 1 | H6: 1 | I6: =IF(C6="不适用","N/A",IF(D6<>"√",0,IF((E6="√")*AND(F6="√"),1,IF((E6<>"√")*AND(F6="√"),0.5*G6,IF((E6="√")*AND(F6<>"√"),0.5*H6,IF((E6<>"√")*AND(F6<>"√"),0.25*G6*H6)))))) | J6: =IF(I6="N/A","不适用",IF(I6=1,"符合",IF(I6=0,"不符合","部分符合"))) | N6: =IF(I6="N/A","N/A",整体测评!O$6/M$5) | O6: =IF(I6="N/A","N/A",I6*N6) | P6: =IF(I6="N/A","N/A",N6-O6)
B7: 智慧缴费系统与吴忠水发之间的通道 | C7: 适用 | D7: × | E7: / | F7: / | G7: 1 | H7: 1 | I7: =IF(C7="不适用","N/A",IF(D7<>"√",0,IF((E7="√")*AND(F7="√"),1,IF((E7<>"√")*AND(F7="√"),0.5*G7,IF((E7="√")*AND(F7<>"√"),0.5*H7,IF((E7<>"√")*AND(F7<>"√"),0.25*G7*H7)))))) | J7: =IF(I7="N/A","不适用",IF(I7=1,"符合",IF(I7=0,"不符合","部分符合"))) | N7: =IF(I7="N/A","N/A",整体测评!O$6/M$5) | O7: =IF(I7="N/A","N/A",I7*N7) | P7: =IF(I7="N/A","N/A",N7-O7)
B8: 智慧缴费系统与高速缴费之间的通道 | C8: 适用 | D8: × | E8: / | F8: / | G8: 1 | H8: 1 | I8: =IF(C8="不适用","N/A",IF(D8<>"√",0,IF((E8="√")*AND(F8="√"),1,IF((E8<>"√")*AND(F8="√"),0.5*G8,IF((E8="√")*AND(F8<>"√"),0.5*H8,IF((E8<>"√")*AND(F8<>"√"),0.25*G8*H8)))))) | J8: =IF(I8="N/A","不适用",IF(I8=1,"符合",IF(I8=0,"不符合","部分符合"))) | N8: =IF(I8="N/A","N/A",整体测评!O$6/M$5) | O8: =IF(I8="N/A","N/A",I8*N8) | P8: =IF(I8="N/A","N/A",N8-O8)
B9: 智慧缴费系统与新南燃气之间的通道 | C9: 适用 | D9: × | E9: / | F9: / | G9: 1 | H9: 1 | I9: =IF(C9="不适用","N/A",IF(D9<>"√",0,IF((E9="√")*AND(F9="√"),1,IF((E9<>"√")*AND(F9="√"),0.5*G9,IF((E9="√")*AND(F9<>"√"),0.5*H9,IF((E9<>"√")*AND(F9<>"√"),0.25*G9*H9)))))) | J9: =IF(I9="N/A","不适用",IF(I9=1,"符合",IF(I9=0,"不符合","部分符合"))) | N9: =IF(I9="N/A","N/A",整体测评!O$6/M$5) | O9: =IF(I9="N/A","N/A",I9*N9) | P9: =IF(I9="N/A","N/A",N9-O9)
B10: PC端访问现金管理系统的通道 | C10: 适用 | D10: × | E10: / | F10: / | G10: 1 | H10: 1 | I10: =IF(C10="不适用","N/A",IF(D10<>"√",0,IF((E10="√")*AND(F10="√"),1,IF((E10<>"√")*AND(F10="√"),0.5*G10,IF((E10="√")*AND(F10<>"√"),0.5*H10,IF((E10<>"√")*AND(F10<>"√"),0.25*G10*H10)))))) | J10: =IF(I10="N/A","不适用",IF(I10=1,"符合",IF(I10=0,"不符合","部分符合"))) | N10: =IF(I10="N/A","N/A",整体测评!O$6/M$5) | O10: =IF(I10="N/A","N/A",I10*N10) | P10: =IF(I10="N/A","N/A",N10-O10)
B11: 现金管理系统与国电之间的通道 | C11: 适用 | D11: × | E11: / | F11: / | G11: 1 | H11: 1 | I11: =IF(C11="不适用","N/A",IF(D11<>"√",0,IF((E11="√")*AND(F11="√"),1,IF((E11<>"√")*AND(F11="√"),0.5*G11,IF((E11="√")*AND(F11<>"√"),0.5*H11,IF((E11<>"√")*AND(F11<>"√"),0.25*G11*H11)))))) | J11: =IF(I11="N/A","不适用",IF(I11=1,"符合",IF(I11=0,"不符合","部分符合"))) | N11: =IF(I11="N/A","N/A",整体测评!O$6/M$5) | O11: =IF(I11="N/A","N/A",I11*N11) | P11: =IF(I11="N/A","N/A",N11-O11)
B12: 现金管理系统与监狱管理局之间的通道 | C12: 适用 | D12: × | E12: / | F12: / | G12: 1 | H12: 1 | I12: =IF(C12="不适用","N/A",IF(D12<>"√",0,IF((E12="√")*AND(F12="√"),1,IF((E12<>"√")*AND(F12="√"),0.5*G12,IF((E12="√")*AND(F12<>"√"),0.5*H12,IF((E12<>"√")*AND(F12<>"√"),0.25*G12*H12)))))) | J12: =IF(I12="N/A","不适用",IF(I12=1,"符合",IF(I12=0,"不符合","部分符合"))) | N12: =IF(I12="N/A","N/A",整体测评!O$6/M$5) | O12: =IF(I12="N/A","N/A",I12*N12) | P12: =IF(I12="N/A","N/A",N12-O12)
B13: 现金管理系统与烟草之间的通道 | C13: 适用 | D13: × | E13: / | F13: / | G13: 1 | H13: 1 | I13: =IF(C13="不适用","N/A",IF(D13<>"√",0,IF((E13="√")*AND(F13="√"),1,IF((E13<>"√")*AND(F13="√"),0.5*G13,IF((E13="√")*AND(F13<>"√"),0.5*H13,IF((E13<>"√")*AND(F13<>"√"),0.25*G13*H13)))))) | J13: =IF(I13="N/A","不适用",IF(I13=1,"符合",IF(I13=0,"不符合","部分符合"))) | N13: =IF(I13="N/A","N/A",整体测评!O$6/M$5) | O13: =IF(I13="N/A","N/A",I13*N13) | P13: =IF(I13="N/A","N/A",N13-O13)
B14: 现金管理系统与预售房之间的通道 | C14: 适用 | D14: × | E14: / | F14: / | G14: 1 | H14: 1 | I14: =IF(C14="不适用","N/A",IF(D14<>"√",0,IF((E14="√")*AND(F14="√"),1,IF((E14<>"√")*AND(F14="√"),0.5*G14,IF((E14="√")*AND(F14<>"√"),0.5*H14,IF((E14<>"√")*AND(F14<>"√"),0.25*G14*H14)))))) | J14: =IF(I14="N/A","不适用",IF(I14=1,"符合",IF(I14=0,"不符合","部分符合"))) | N14: =IF(I14="N/A","N/A",整体测评!O$6/M$5) | O14: =IF(I14="N/A","N/A",I14*N14) | P14: =IF(I14="N/A","N/A",N14-O14)
B15: 新一代电子不停车收费系统与公路局之间的通道 | C15: 适用 | D15: × | E15: / | F15: / | G15: 1 | H15: 1 | I15: =IF(C15="不适用","N/A",IF(D15<>"√",0,IF((E15="√")*AND(F15="√"),1,IF((E15<>"√")*AND(F15="√"),0.5*G15,IF((E15="√")*AND(F15<>"√"),0.5*H15,IF((E15<>"√")*AND(F15<>"√"),0.25*G15*H15)))))) | J15: =IF(I15="N/A","不适用",IF(I15=1,"符合",IF(I15=0,"不符合","部分符合"))) | N15: =IF(I15="N/A","N/A",整体测评!O$6/M$5) | O15: =IF(I15="N/A","N/A",I15*N15) | P15: =IF(I15="N/A","N/A",N15-O15)
B16: 代收付系统与医保厅之间的通道 | C16: 适用 | D16: × | E16: / | F16: / | G16: 1 | H16: 1 | I16: =IF(C16="不适用","N/A",IF(D16<>"√",0,IF((E16="√")*AND(F16="√"),1,IF((E16<>"√")*AND(F16="√"),0.5*G16,IF((E16="√")*AND(F16<>"√"),0.5*H16,IF((E16<>"√")*AND(F16<>"√"),0.25*G16*H16)))))) | J16: =IF(I16="N/A","不适用",IF(I16=1,"符合",IF(I16=0,"不符合","部分符合"))) | N16: =IF(I16="N/A","N/A",整体测评!O$6/M$5) | O16: =IF(I16="N/A","N/A",I16*N16) | P16: =IF(I16="N/A","N/A",N16-O16)
B17: 代收付系统与学校之间的通道 | C17: 适用 | D17: × | E17: / | F17: / | G17: 1 | H17: 1 | I17: =IF(C17="不适用","N/A",IF(D17<>"√",0,IF((E17="√")*AND(F17="√"),1,IF((E17<>"√")*AND(F17="√"),0.5*G17,IF((E17="√")*AND(F17<>"√"),0.5*H17,IF((E17<>"√")*AND(F17<>"√"),0.25*G17*H17)))))) | J17: =IF(I17="N/A","不适用",IF(I17=1,"符合",IF(I17=0,"不符合","部分符合"))) | N17: =IF(I17="N/A","N/A",整体测评!O$6/M$5) | O17: =IF(I17="N/A","N/A",I17*N17) | P17: =IF(I17="N/A","N/A",N17-O17)
... B38: 勿删 | C38: 不适用 | D38: √ | E38: √ | F38: √ | G38: 1 | H38: 1 | I38: =IF(C38="不适用","N/A",IF(D38<>"√",0,IF((E38="√")*AND(F38="√"),1,IF((E38<>"√")*AND(F38="√"),0.5*G38,IF((E38="√")*AND(F38<>"√"),0.5*H38,IF((E38<>"√")*AND(F38<>"√"),0.25*G38*H38)))))) | J38: =IF(I38="N/A","不适用",IF(I38=1,"符合",IF(I38=0,"不符合","部分符合"))) | N38: =IF(I38="N/A","N/A",整体测评!O$6/M$5) | O38: =IF(I38="N/A","N/A",I38*N38) | P38: =IF(I38="N/A","N/A",N38-O38)
A39: 通信数据完整性 | B39: 智慧缴费系统小程序通道 | C39: 适用 | D39: √ | E39: × | F39: × | G39: 1 | H39: 1 | I39: =IF(C39="不适用","N/A",IF(D39<>"√",0,IF((E39="√")*AND(F39="√"),1,IF((E39<>"√")*AND(F39="√"),0.5*G39,IF((E39="√")*AND(F39<>"√"),0.5*H39,IF((E39<>"√")*AND(F39<>"√"),0.25*G39*H39)))))) | J39: =IF(I39="N/A","不适用",IF(I39=1,"符合",IF(I39=0,"不符合","部分符合"))) | K39: =IF(COUNTIF($I39:$I72,"N/A")=COUNTA($I39:$I72),"N/A",AVERAGE($I39:$I72)) | L39: =IF(K39="N/A","不适用",IF(K39=1,"符合",IF(K39=0,"不符合","部分符合"))) | M39: =(COUNTA($C39:$C72)-COUNTIF($C39:$C72,"不适用")) | N39: =IF(I39="N/A","N/A",整体测评!O$7/M$39) | O39: =IF(I39="N/A","N/A",I39*N39) | P39: =IF(I39="N/A","N/A",N39-O39)
B40: 智慧缴费系统与吴忠供热之间的通道 | C40: 适用 | D40: × | E40: / | F40: / | G40: 1 | H40: 1 | I40: =IF(C40="不适用","N/A",IF(D40<>"√",0,IF((E40="√")*AND(F40="√"),1,IF((E40<>"√")*AND(F40="√"),0.5*G40,IF((E40="√")*AND(F40<>"√"),0.5*H40,IF((E40<>"√")*AND(F40<>"√"),0.25*G40*H40)))))) | J40: =IF(I40="N/A","不适用",IF(I40=1,"符合",IF(I40=0,"不符合","部分符合"))) | N40: =IF(I40="N/A","N/A",整体测评!O$7/M$39) | O40: =IF(I40="N/A","N/A",I40*N40) | P40: =IF(I40="N/A","N/A",N40-O40)
B41: 智慧缴费系统与吴忠水发之间的通道 | C41: 适用 | D41: × | E41: / | F41: / | G41: 1 | H41: 1 | I41: =IF(C41="不适用","N/A",IF(D41<>"√",0,IF((E41="√")*AND(F41="√"),1,IF((E41<>"√")*AND(F41="√"),0.5*G41,IF((E41="√")*AND(F41<>"√"),0.5*H41,IF((E41<>"√")*AND(F41<>"√"),0.25*G41*H41)))))) | J41: =IF(I41="N/A","不适用",IF(I41=1,"符合",IF(I41=0,"不符合","部分符合"))) | N41: =IF(I41="N/A","N/A",整体测评!O$7/M$39) | O41: =IF(I41="N/A","N/A",I41*N41) | P41: =IF(I41="N/A","N/A",N41-O41)
B42: 智慧缴费系统与高速缴费之间的通道 | C42: 适用 | D42: × | E42: / | F42: / | G42: 1 | H42: 1 | I42: =IF(C42="不适用","N/A",IF(D42<>"√",0,IF((E42="√")*AND(F42="√"),1,IF((E42<>"√")*AND(F42="√"),0.5*G42,IF((E42="√")*AND(F42<>"√"),0.5*H42,IF((E42<>"√")*AND(F42<>"√"),0.25*G42*H42)))))) | J42: =IF(I42="N/A","不适用",IF(I42=1,"符合",IF(I42=0,"不符合","部分符合"))) | N42: =IF(I42="N/A","N/A",整体测评!O$7/M$39) | O42: =IF(I42="N/A","N/A",I42*N42) | P42: =IF(I42="N/A","N/A",N42-O42)
B43: 智慧缴费系统与新南燃气之间的通道 | C43: 适用 | D43: × | E43: / | F43: / | G43: 1 | H43: 1 | I43: =IF(C43="不适用","N/A",IF(D43<>"√",0,IF((E43="√")*AND(F43="√"),1,IF((E43<>"√")*AND(F43="√"),0.5*G43,IF((E43="√")*AND(F43<>"√"),0.5*H43,IF((E43<>"√")*AND(F43<>"√"),0.25*G43*H43)))))) | J43: =IF(I43="N/A","不适用",IF(I43=1,"符合",IF(I43=0,"不符合","部分符合"))) | N43: =IF(I43="N/A","N/A",整体测评!O$7/M$39) | O43: =IF(I43="N/A","N/A",I43*N43) | P43: =IF(I43="N/A","N/A",N43-O43)
B44: PC端访问现金管理系统的通道 | C44: 适用 | D44: × | E44: / | F44: / | G44: 1 | H44: 1 | I44: =IF(C44="不适用","N/A",IF(D44<>"√",0,IF((E44="√")*AND(F44="√"),1,IF((E44<>"√")*AND(F44="√"),0.5*G44,IF((E44="√")*AND(F44<>"√"),0.5*H44,IF((E44<>"√")*AND(F44<>"√"),0.25*G44*H44)))))) | J44: =IF(I44="N/A","不适用",IF(I44=1,"符合",IF(I44=0,"不符合","部分符合"))) | N44: =IF(I44="N/A","N/A",整体测评!O$7/M$39) | O44: =IF(I44="N/A","N/A",I44*N44) | P44: =IF(I44="N/A","N/A",N44-O44)
B45: 现金管理系统与国电之间的通道 | C45: 适用 | D45: × | E45: / | F45: / | G45: 1 | H45: 1 | I45: =IF(C45="不适用","N/A",IF(D45<>"√",0,IF((E45="√")*AND(F45="√"),1,IF((E45<>"√")*AND(F45="√"),0.5*G45,IF((E45="√")*AND(F45<>"√"),0.5*H45,IF((E45<>"√")*AND(F45<>"√"),0.25*G45*H45)))))) | J45: =IF(I45="N/A","不适用",IF(I45=1,"符合",IF(I45=0,"不符合","部分符合"))) | N45: =IF(I45="N/A","N/A",整体测评!O$7/M$39) | O45: =IF(I45="N/A","N/A",I45*N45) | P45: =IF(I45="N/A","N/A",N45-O45)
B46: 现金管理系统与监狱管理局之间的通道 | C46: 适用 | D46: × | E46: / | F46: / | G46: 1 | H46: 1 | I46: =IF(C46="不适用","N/A",IF(D46<>"√",0,IF((E46="√")*AND(F46="√"),1,IF((E46<>"√")*AND(F46="√"),0.5*G46,IF((E46="√")*AND(F46<>"√"),0.5*H46,IF((E46<>"√")*AND(F46<>"√"),0.25*G46*H46)))))) | J46: =IF(I46="N/A","不适用",IF(I46=1,"符合",IF(I46=0,"不符合","部分符合"))) | N46: =IF(I46="N/A","N/A",整体测评!O$7/M$39) | O46: =IF(I46="N/A","N/A",I46*N46) | P46: =IF(I46="N/A","N/A",N46-O46)
B47: 现金管理系统与烟草之间的通道 | C47: 适用 | D47: × | E47: / | F47: / | G47: 1 | H47: 1 | I47: =IF(C47="不适用","N/A",IF(D47<>"√",0,IF((E47="√")*AND(F47="√"),1,IF((E47<>"√")*AND(F47="√"),0.5*G47,IF((E47="√")*AND(F47<>"√"),0.5*H47,IF((E47<>"√")*AND(F47<>"√"),0.25*G47*H47)))))) | J47: =IF(I47="N/A","不适用",IF(I47=1,"符合",IF(I47=0,"不符合","部分符合"))) | N47: =IF(I47="N/A","N/A",整体测评!O$7/M$39) | O47: =IF(I47="N/A","N/A",I47*N47) | P47: =IF(I47="N/A","N/A",N47-O47)
B48: 现金管理系统与预售房之间的通道 | C48: 适用 | D48: × | E48: / | F48: / | G48: 1 | H48: 1 | I48: =IF(C48="不适用","N/A",IF(D48<>"√",0,IF((E48="√")*AND(F48="√"),1,IF((E48<>"√")*AND(F48="√"),0.5*G48,IF((E48="√")*AND(F48<>"√"),0.5*H48,IF((E48<>"√")*AND(F48<>"√"),0.25*G48*H48)))))) | J48: =IF(I48="N/A","不适用",IF(I48=1,"符合",IF(I48=0,"不符合","部分符合"))) | N48: =IF(I48="N/A","N/A",整体测评!O$7/M$39) | O48: =IF(I48="N/A","N/A",I48*N48) | P48: =IF(I48="N/A","N/A",N48-O48)
B49: 新一代电子不停车收费系统与公路局之间的通道 | C49: 适用 | D49: × | E49: / | F49: / | G49: 1 | H49: 1 | I49: =IF(C49="不适用","N/A",IF(D49<>"√",0,IF((E49="√")*AND(F49="√"),1,IF((E49<>"√")*AND(F49="√"),0.5*G49,IF((E49="√")*AND(F49<>"√"),0.5*H49,IF((E49<>"√")*AND(F49<>"√"),0.25*G49*H49)))))) | J49: =IF(I49="N/A","不适用",IF(I49=1,"符合",IF(I49=0,"不符合","部分符合"))) | N49: =IF(I49="N/A","N/A",整体测评!O$7/M$39) | O49: =IF(I49="N/A","N/A",I49*N49) | P49: =IF(I49="N/A","N/A",N49-O49)
B50: 代收付系统与医保厅之间的通道 | C50: 适用 | D50: × | E50: / | F50: / | G50: 1 | H50: 1 | I50: =IF(C50="不适用","N/A",IF(D50<>"√",0,IF((E50="√")*AND(F50="√"),1,IF((E50<>"√")*AND(F50="√"),0.5*G50,IF((E50="√")*AND(F50<>"√"),0.5*H50,IF((E50<>"√")*AND(F50<>"√"),0.25*G50*H50)))))) | J50: =IF(I50="N/A","不适用",IF(I50=1,"符合",IF(I50=0,"不符合","部分符合"))) | N50: =IF(I50="N/A","N/A",整体测评!O$7/M$39) | O50: =IF(I50="N/A","N/A",I50*N50) | P50: =IF(I50="N/A","N/A",N50-O50)
B51: 代收付系统与学校之间的通道 | C51: 适用 | D51: × | E51: / | F51: / | G51: 1 | H51: 1 | I51: =IF(C51="不适用","N/A",IF(D51<>"√",0,IF((E51="√")*AND(F51="√"),1,IF((E51<>"√")*AND(F51="√"),0.5*G51,IF((E51="√")*AND(F51<>"√"),0.5*H51,IF((E51<>"√")*AND(F51<>"√"),0.25*G51*H51)))))) | J51: =IF(I51="N/A","不适用",IF(I51=1,"符合",IF(I51=0,"不符合","部分符合"))) | N51: =IF(I51="N/A","N/A",整体测评!O$7/M$39) | O51: =IF(I51="N/A","N/A",I51*N51) | P51: =IF(I51="N/A","N/A",N51-O51)
... B72: 勿删 | C72: 不适用 | D72: √ | E72: √ | F72: √ | G72: 1 | H72: 1 | I72: =IF(C72="不适用","N/A",IF(D72<>"√",0,IF((E72="√")*AND(F72="√"),1,IF((E72<>"√")*AND(F72="√"),0.5*G72,IF((E72="√")*AND(F72<>"√"),0.5*H72,IF((E72<>"√")*AND(F72<>"√"),0.25*G72*H72)))))) | J72: =IF(I72="N/A","不适用",IF(I72=1,"符合",IF(I72=0,"不符合","部分符合"))) | N72: =IF(I72="N/A","N/A",整体测评!O$7/M$39) | O72: =IF(I72="N/A","N/A",I72*N72) | P72: =IF(I72="N/A","N/A",N72-O72)
A73: 通信过程中重要数据的机密性 | B73: 智慧缴费系统小程序通道 | C73: 适用 | D73: √ | E73: × | F73: × | G73: 1 | H73: 1 | I73: =IF(C73="不适用","N/A",IF(D73<>"√",0,IF((E73="√")*AND(F73="√"),1,IF((E73<>"√")*AND(F73="√"),0.5*G73,IF((E73="√")*AND(F73<>"√"),0.5*H73,IF((E73<>"√")*AND(F73<>"√"),0.25*G73*H73)))))) | J73: =IF(I73="N/A","不适用",IF(I73=1,"符合",IF(I73=0,"不符合","部分符合"))) | K73: =IF(COUNTIF($I73:$I106,"N/A")=COUNTA($I73:$I106),"N/A",AVERAGE($I73:$I106)) | L73: =IF(K73="N/A","不适用",IF(K73=1,"符合",IF(K73=0,"不符合","部分符合"))) | M73: =(COUNTA($C73:$C106)-COUNTIF($C73:$C106,"不适用")) | N73: =IF(I73="N/A","N/A",整体测评!O$8/M$73) | O73: =IF(I73="N/A","N/A",I73*N73) | P73: =IF(I73="N/A","N/A",N73-O73)
B74: 智慧缴费系统与吴忠供热之间的通道 | C74: 适用 | D74: × | E74: / | F74: / | G74: 1 | H74: 1 | I74: =IF(C74="不适用","N/A",IF(D74<>"√",0,IF((E74="√")*AND(F74="√"),1,IF((E74<>"√")*AND(F74="√"),0.5*G74,IF((E74="√")*AND(F74<>"√"),0.5*H74,IF((E74<>"√")*AND(F74<>"√"),0.25*G74*H74)))))) | J74: =IF(I74="N/A","不适用",IF(I74=1,"符合",IF(I74=0,"不符合","部分符合"))) | N74: =IF(I74="N/A","N/A",整体测评!O$8/M$73) | O74: =IF(I74="N/A","N/A",I74*N74) | P74: =IF(I74="N/A","N/A",N74-O74)
B75: 智慧缴费系统与吴忠水发之间的通道 | C75: 适用 | D75: × | E75: / | F75: / | G75: 1 | H75: 1 | I75: =IF(C75="不适用","N/A",IF(D75<>"√",0,IF((E75="√")*AND(F75="√"),1,IF((E75<>"√")*AND(F75="√"),0.5*G75,IF((E75="√")*AND(F75<>"√"),0.5*H75,IF((E75<>"√")*AND(F75<>"√"),0.25*G75*H75)))))) | J75: =IF(I75="N/A","不适用",IF(I75=1,"符合",IF(I75=0,"不符合","部分符合"))) | N75: =IF(I75="N/A","N/A",整体测评!O$8/M$73) | O75: =IF(I75="N/A","N/A",I75*N75) | P75: =IF(I75="N/A","N/A",N75-O75)
B76: 智慧缴费系统与高速缴费之间的通道 | C76: 适用 | D76: × | E76: / | F76: / | G76: 1 | H76: 1 | I76: =IF(C76="不适用","N/A",IF(D76<>"√",0,IF((E76="√")*AND(F76="√"),1,IF((E76<>"√")*AND(F76="√"),0.5*G76,IF((E76="√")*AND(F76<>"√"),0.5*H76,IF((E76<>"√")*AND(F76<>"√"),0.25*G76*H76)))))) | J76: =IF(I76="N/A","不适用",IF(I76=1,"符合",IF(I76=0,"不符合","部分符合"))) | N76: =IF(I76="N/A","N/A",整体测评!O$8/M$73) | O76: =IF(I76="N/A","N/A",I76*N76) | P76: =IF(I76="N/A","N/A",N76-O76)
B77: 智慧缴费系统与新南燃气之间的通道 | C77: 适用 | D77: × | E77: / | F77: / | G77: 1 | H77: 1 | I77: =IF(C77="不适用","N/A",IF(D77<>"√",0,IF((E77="√")*AND(F77="√"),1,IF((E77<>"√")*AND(F77="√"),0.5*G77,IF((E77="√")*AND(F77<>"√"),0.5*H77,IF((E77<>"√")*AND(F77<>"√"),0.25*G77*H77)))))) | J77: =IF(I77="N/A","不适用",IF(I77=1,"符合",IF(I77=0,"不符合","部分符合"))) | N77: =IF(I77="N/A","N/A",整体测评!O$8/M$73) | O77: =IF(I77="N/A","N/A",I77*N77) | P77: =IF(I77="N/A","N/A",N77-O77)
B78: PC端访问现金管理系统的通道 | C78: 适用 | D78: × | E78: / | F78: / | G78: 1 | H78: 1 | I78: =IF(C78="不适用","N/A",IF(D78<>"√",0,IF((E78="√")*AND(F78="√"),1,IF((E78<>"√")*AND(F78="√"),0.5*G78,IF((E78="√")*AND(F78<>"√"),0.5*H78,IF((E78<>"√")*AND(F78<>"√"),0.25*G78*H78)))))) | J78: =IF(I78="N/A","不适用",IF(I78=1,"符合",IF(I78=0,"不符合","部分符合"))) | N78: =IF(I78="N/A","N/A",整体测评!O$8/M$73) | O78: =IF(I78="N/A","N/A",I78*N78) | P78: =IF(I78="N/A","N/A",N78-O78)
B79: 现金管理系统与国电之间的通道 | C79: 适用 | D79: × | E79: / | F79: / | G79: 1 | H79: 1 | I79: =IF(C79="不适用","N/A",IF(D79<>"√",0,IF((E79="√")*AND(F79="√"),1,IF((E79<>"√")*AND(F79="√"),0.5*G79,IF((E79="√")*AND(F79<>"√"),0.5*H79,IF((E79<>"√")*AND(F79<>"√"),0.25*G79*H79)))))) | J79: =IF(I79="N/A","不适用",IF(I79=1,"符合",IF(I79=0,"不符合","部分符合"))) | N79: =IF(I79="N/A","N/A",整体测评!O$8/M$73) | O79: =IF(I79="N/A","N/A",I79*N79) | P79: =IF(I79="N/A","N/A",N79-O79)
B80: 现金管理系统与监狱管理局之间的通道 | C80: 适用 | D80: × | E80: / | F80: / | G80: 1 | H80: 1 | I80: =IF(C80="不适用","N/A",IF(D80<>"√",0,IF((E80="√")*AND(F80="√"),1,IF((E80<>"√")*AND(F80="√"),0.5*G80,IF((E80="√")*AND(F80<>"√"),0.5*H80,IF((E80<>"√")*AND(F80<>"√"),0.25*G80*H80)))))) | J80: =IF(I80="N/A","不适用",IF(I80=1,"符合",IF(I80=0,"不符合","部分符合"))) | N80: =IF(I80="N/A","N/A",整体测评!O$8/M$73) | O80: =IF(I80="N/A","N/A",I80*N80) | P80: =IF(I80="N/A","N/A",N80-O80)
B81: 现金管理系统与烟草之间的通道 | C81: 适用 | D81: × | E81: / | F81: / | G81: 1 | H81: 1 | I81: =IF(C81="不适用","N/A",IF(D81<>"√",0,IF((E81="√")*AND(F81="√"),1,IF((E81<>"√")*AND(F81="√"),0.5*G81,IF((E81="√")*AND(F81<>"√"),0.5*H81,IF((E81<>"√")*AND(F81<>"√"),0.25*G81*H81)))))) | J81: =IF(I81="N/A","不适用",IF(I81=1,"符合",IF(I81=0,"不符合","部分符合"))) | N81: =IF(I81="N/A","N/A",整体测评!O$8/M$73) | O81: =IF(I81="N/A","N/A",I81*N81) | P81: =IF(I81="N/A","N/A",N81-O81)
...

Sheet 3设备和计算安全
A1: 设备和计算安全
A3: 测评单元 | B3: 测评对象 | C3: 适用情况 | D3: 涉及情况 | I3: 分值 Si,j,k | J3: 符合情况 | K3: 测评单元得分 S i, j | L3: 单元测评结果 | M3: 有效对象数量 | N3: 所占分值 | O3: 已得分值 | P3: 丢失分值
D4: 密码使用有效性D | E4: 密码算法/技术 合规性A | F4: 密钥管理安全K | G4: Ra | H4: Rk
A5: 身份鉴别 | B5: OBS管理平台 | C5: 适用 | D5: √ | E5: √ | F5: √ | G5: 1 | H5: 1 | I5: =IF(C5="不适用","N/A",IF(D5<>"√",0,IF((E5="√")*AND(F5="√"),1,IF((E5<>"√")*AND(F5="√"),0.5*G5,IF((E5="√")*AND(F5<>"√"),0.5*H5,IF((E5<>"√")*AND(F5<>"√"),0.25*G5*H5)))))) | J5: =IF(I5="N/A","不适用",IF(I5=1,"符合",IF(I5=0,"不符合","部分符合"))) | K5: =IF(COUNTIF($I5:$I13,"N/A")=COUNTA($I5:$I13),"N/A",AVERAGE($I5:$I13)) | L5: =IF(K5="N/A","不适用",IF(K5=1,"符合",IF(K5=0,"不符合","部分符合"))) | M5: =(COUNTA($C5:$C13)-COUNTIF($C5:$C13,"不适用")) | N5: =IF(I5="N/A","N/A",整体测评!O$11/M$5) | O5: =IF(I5="N/A","N/A",I5*N5) | P5: =IF(I5="N/A","N/A",N5-O5)
B6: 麒麟V10服务器 | C6: 适用 | D6: × | E6: / | F6: / | G6: 1 | H6: 1 | I6: =IF(C6="不适用","N/A",IF(D6<>"√",0,IF((E6="√")*AND(F6="√"),1,IF((E6<>"√")*AND(F6="√"),0.5*G6,IF((E6="√")*AND(F6<>"√"),0.5*H6,IF((E6<>"√")*AND(F6<>"√"),0.25*G6*H6)))))) | J6: =IF(I6="N/A","不适用",IF(I6=1,"符合",IF(I6=0,"不符合","部分符合"))) | N6: =IF(I6="N/A","N/A",整体测评!O$11/M$5) | O6: =IF(I6="N/A","N/A",I6*N6) | P6: =IF(I6="N/A","N/A",N6-O6)
B7: Linux服务器 | C7: 适用 | D7: × | E7: / | F7: / | G7: 1 | H7: 1 | I7: =IF(C7="不适用","N/A",IF(D7<>"√",0,IF((E7="√")*AND(F7="√"),1,IF((E7<>"√")*AND(F7="√"),0.5*G7,IF((E7="√")*AND(F7<>"√"),0.5*H7,IF((E7<>"√")*AND(F7<>"√"),0.25*G7*H7)))))) | J7: =IF(I7="N/A","不适用",IF(I7=1,"符合",IF(I7=0,"不符合","部分符合"))) | N7: =IF(I7="N/A","N/A",整体测评!O$11/M$5) | O7: =IF(I7="N/A","N/A",I7*N7) | P7: =IF(I7="N/A","N/A",N7-O7)
B8: Oracle数据库 | C8: 适用 | D8: × | E8: / | F8: / | G8: 1 | H8: 1 | I8: =IF(C8="不适用","N/A",IF(D8<>"√",0,IF((E8="√")*AND(F8="√"),1,IF((E8<>"√")*AND(F8="√"),0.5*G8,IF((E8="√")*AND(F8<>"√"),0.5*H8,IF((E8<>"√")*AND(F8<>"√"),0.25*G8*H8)))))) | J8: =IF(I8="N/A","不适用",IF(I8=1,"符合",IF(I8=0,"不符合","部分符合"))) | N8: =IF(I8="N/A","N/A",整体测评!O$11/M$5) | O8: =IF(I8="N/A","N/A",I8*N8) | P8: =IF(I8="N/A","N/A",N8-O8)
B9: 签名验签服务器 | C9: 适用 | D9: × | E9: / | F9: / | G9: 1 | H9: 1 | I9: =IF(C9="不适用","N/A",IF(D9<>"√",0,IF((E9="√")*AND(F9="√"),1,IF((E9<>"√")*AND(F9="√"),0.5*G9,IF((E9="√")*AND(F9<>"√"),0.5*H9,IF((E9<>"√")*AND(F9<>"√"),0.25*G9*H9)))))) | J9: =IF(I9="N/A","不适用",IF(I9=1,"符合",IF(I9=0,"不符合","部分符合"))) | N9: =IF(I9="N/A","N/A",整体测评!O$11/M$5) | O9: =IF(I9="N/A","N/A",I9*N9) | P9: =IF(I9="N/A","N/A",N9-O9)
B10: 服务器密码机 | C10: 适用 | D10: × | E10: / | F10: / | G10: 1 | H10: 1 | I10: =IF(C10="不适用","N/A",IF(D10<>"√",0,IF((E10="√")*AND(F10="√"),1,IF((E10<>"√")*AND(F10="√"),0.5*G10,IF((E10="√")*AND(F10<>"√"),0.5*H10,IF((E10<>"√")*AND(F10<>"√"),0.25*G10*H10)))))) | J10: =IF(I10="N/A","不适用",IF(I10=1,"符合",IF(I10=0,"不符合","部分符合"))) | N10: =IF(I10="N/A","N/A",整体测评!O$11/M$5) | O10: =IF(I10="N/A","N/A",I10*N10) | P10: =IF(I10="N/A","N/A",N10-O10)
B11: TDSQL数据库 | C11: 适用 | D11: × | E11: / | F11: / | G11: 1 | H11: 1 | I11: =IF(C11="不适用","N/A",IF(D11<>"√",0,IF((E11="√")*AND(F11="√"),1,IF((E11<>"√")*AND(F11="√"),0.5*G11,IF((E11="√")*AND(F11<>"√"),0.5*H11,IF((E11<>"√")*AND(F11<>"√"),0.25*G11*H11)))))) | J11: =IF(I11="N/A","不适用",IF(I11=1,"符合",IF(I11=0,"不符合","部分符合"))) | N11: =IF(I11="N/A","N/A",整体测评!O$11/M$5) | O11: =IF(I11="N/A","N/A",I11*N11) | P11: =IF(I11="N/A","N/A",N11-O11)
B12: SOM安全运维管理平台 | C12: 适用 | D12: √ | E12: √ | F12: × | G12: 1 | H12: 1.2 | I12: =IF(C12="不适用","N/A",IF(D12<>"√",0,IF((E12="√")*AND(F12="√"),1,IF((E12<>"√")*AND(F12="√"),0.5*G12,IF((E12="√")*AND(F12<>"√"),0.5*H12,IF((E12<>"√")*AND(F12<>"√"),0.25*G12*H12)))))) | J12: =IF(I12="N/A","不适用",IF(I12=1,"符合",IF(I12=0,"不符合","部分符合"))) | N12: =IF(I12="N/A","N/A",整体测评!O$11/M$5) | O12: =IF(I12="N/A","N/A",I12*N12) | P12: =IF(I12="N/A","N/A",N12-O12)
B13: 勿删 | C13: 不适用 | G13: 1 | H13: 1 | I13: =IF(C13="不适用","N/A",IF(D13<>"√",0,IF((E13="√")*AND(F13="√"),1,IF((E13<>"√")*AND(F13="√"),0.5*G13,IF((E13="√")*AND(F13<>"√"),0.5*H13,IF((E13<>"√")*AND(F13<>"√"),0.25*G13*H13)))))) | J13: =IF(I13="N/A","不适用",IF(I13=1,"符合",IF(I13=0,"不符合","部分符合"))) | N13: =IF(I13="N/A","N/A",整体测评!O$11/M$5) | O13: =IF(I13="N/A","N/A",I13*N13) | P13: =IF(I13="N/A","N/A",N13-O13)
A14: 远程管理通道安全 | B14: OBS管理平台 | C14: 适用 | D14: √ | E14: × | F14: × | G14: 1 | H14: 1 | I14: =IF(C14="不适用","N/A",IF(D14<>"√",0,IF((E14="√")*AND(F14="√"),1,IF((E14<>"√")*AND(F14="√"),0.5*G14,IF((E14="√")*AND(F14<>"√"),0.5*H14,IF((E14<>"√")*AND(F14<>"√"),0.25*G14*H14)))))) | J14: =IF(I14="N/A","不适用",IF(I14=1,"符合",IF(I14=0,"不符合","部分符合"))) | K14: =IF(COUNTIF($I14:$I22,"N/A")=COUNTA($I14:$I22),"N/A",AVERAGE($I14:$I22)) | L14: =IF(K14="N/A","不适用",IF(K14=1,"符合",IF(K14=0,"不符合","部分符合"))) | M14: =(COUNTA($C14:$C22)-COUNTIF($C14:$C22,"不适用")) | N14: =IF(I14="N/A","N/A",整体测评!O$12/M$14) | O14: =IF(I14="N/A","N/A",I14*N14) | P14: =IF(I14="N/A","N/A",N14-O14)
B15: 麒麟V10服务器 | C15: 适用 | D15: √ | E15: × | F15: × | G15: 1 | H15: 1 | I15: =IF(C15="不适用","N/A",IF(D15<>"√",0,IF((E15="√")*AND(F15="√"),1,IF((E15<>"√")*AND(F15="√"),0.5*G15,IF((E15="√")*AND(F15<>"√"),0.5*H15,IF((E15<>"√")*AND(F15<>"√"),0.25*G15*H15)))))) | J15: =IF(I15="N/A","不适用",IF(I15=1,"符合",IF(I15=0,"不符合","部分符合"))) | N15: =IF(I15="N/A","N/A",整体测评!O$12/M$14) | O15: =IF(I15="N/A","N/A",I15*N15) | P15: =IF(I15="N/A","N/A",N15-O15)
B16: Linux服务器 | C16: 适用 | D16: √ | E16: × | F16: × | G16: 1 | H16: 1 | I16: =IF(C16="不适用","N/A",IF(D16<>"√",0,IF((E16="√")*AND(F16="√"),1,IF((E16<>"√")*AND(F16="√"),0.5*G16,IF((E16="√")*AND(F16<>"√"),0.5*H16,IF((E16<>"√")*AND(F16<>"√"),0.25*G16*H16)))))) | J16: =IF(I16="N/A","不适用",IF(I16=1,"符合",IF(I16=0,"不符合","部分符合"))) | N16: =IF(I16="N/A","N/A",整体测评!O$12/M$14) | O16: =IF(I16="N/A","N/A",I16*N16) | P16: =IF(I16="N/A","N/A",N16-O16)
B17: Oracle数据库 | C17: 适用 | D17: × | E17: / | F17: / | G17: 1 | H17: 1 | I17: =IF(C17="不适用","N/A",IF(D17<>"√",0,IF((E17="√")*AND(F17="√"),1,IF((E17<>"√")*AND(F17="√"),0.5*G17,IF((E17="√")*AND(F17<>"√"),0.5*H17,IF((E17<>"√")*AND(F17<>"√"),0.25*G17*H17)))))) | J17: =IF(I17="N/A","不适用",IF(I17=1,"符合",IF(I17=0,"不符合","部分符合"))) | N17: =IF(I17="N/A","N/A",整体测评!O$12/M$14) | O17: =IF(I17="N/A","N/A",I17*N17) | P17: =IF(I17="N/A","N/A",N17-O17)
B18: 签名验签服务器 | C18: 不适用 | D18: × | E18: / | F18: / | I18: =IF(C18="不适用","N/A",IF(D18<>"√",0,IF((E18="√")*AND(F18="√"),1,IF((E18<>"√")*AND(F18="√"),0.5*G18,IF((E18="√")*AND(F18<>"√"),0.5*H18,IF((E18<>"√")*AND(F18<>"√"),0.25*G18*H18)))))) | J18: =IF(I18="N/A","不适用",IF(I18=1,"符合",IF(I18=0,"不符合","部分符合"))) | N18: =IF(I18="N/A","N/A",整体测评!O$12/M$14) | O18: =IF(I18="N/A","N/A",I18*N18) | P18: =IF(I18="N/A","N/A",N18-O18)
B19: 服务器密码机 | C19: 不适用 | D19: × | E19: / | F19: / | G19: 1 | H19: 1 | I19: =IF(C19="不适用","N/A",IF(D19<>"√",0,IF((E19="√")*AND(F19="√"),1,IF((E19<>"√")*AND(F19="√"),0.5*G19,IF((E19="√")*AND(F19<>"√"),0.5*H19,IF((E19<>"√")*AND(F19<>"√"),0.25*G19*H19)))))) | J19: =IF(I19="N/A","不适用",IF(I19=1,"符合",IF(I19=0,"不符合","部分符合"))) | N19: =IF(I19="N/A","N/A",整体测评!O$12/M$14) | O19: =IF(I19="N/A","N/A",I19*N19) | P19: =IF(I19="N/A","N/A",N19-O19)
B20: TDSQL数据库 | C20: 适用 | D20: × | E20: / | F20: / | G20: 1 | H20: 1 | I20: =IF(C20="不适用","N/A",IF(D20<>"√",0,IF((E20="√")*AND(F20="√"),1,IF((E20<>"√")*AND(F20="√"),0.5*G20,IF((E20="√")*AND(F20<>"√"),0.5*H20,IF((E20<>"√")*AND(F20<>"√"),0.25*G20*H20)))))) | J20: =IF(I20="N/A","不适用",IF(I20=1,"符合",IF(I20=0,"不符合","部分符合"))) | N20: =IF(I20="N/A","N/A",整体测评!O$12/M$14) | O20: =IF(I20="N/A","N/A",I20*N20) | P20: =IF(I20="N/A","N/A",N20-O20)
B21: SOM安全运维管理平台 | C21: 适用 | D21: √ | E21: × | F21: × | G21: 1 | H21: 1 | I21: =IF(C21="不适用","N/A",IF(D21<>"√",0,IF((E21="√")*AND(F21="√"),1,IF((E21<>"√")*AND(F21="√"),0.5*G21,IF((E21="√")*AND(F21<>"√"),0.5*H21,IF((E21<>"√")*AND(F21<>"√"),0.25*G21*H21)))))) | J21: =IF(I21="N/A","不适用",IF(I21=1,"符合",IF(I21=0,"不符合","部分符合"))) | N21: =IF(I21="N/A","N/A",整体测评!O$12/M$14) | O21: =IF(I21="N/A","N/A",I21*N21) | P21: =IF(I21="N/A","N/A",N21-O21)
B22: 勿删 | C22: 不适用 | G22: 1 | H22: 1 | I22: =IF(C22="不适用","N/A",IF(D22<>"√",0,IF((E22="√")*AND(F22="√"),1,IF((E22<>"√")*AND(F22="√"),0.5*G22,IF((E22="√")*AND(F22<>"√"),0.5*H22,IF((E22<>"√")*AND(F22<>"√"),0.25*G22*H22)))))) | J22: =IF(I22="N/A","不适用",IF(I22=1,"符合",IF(I22=0,"不符合","部分符合"))) | N22: =IF(I22="N/A","N/A",整体测评!O$12/M$14) | O22: =IF(I22="N/A","N/A",I22*N22) | P22: =IF(I22="N/A","N/A",N22-O22)
A23: 系统资源访问控制信息完整性 | B23: OBS管理平台 | C23: 适用 | D23: √ | E23: √ | F23: √ | G23: 1 | H23: 1 | I23: =IF(C23="不适用","N/A",IF(D23<>"√",0,IF((E23="√")*AND(F23="√"),1,IF((E23<>"√")*AND(F23="√"),0.5*G23,IF((E23="√")*AND(F23<>"√"),0.5*H23,IF((E23<>"√")*AND(F23<>"√"),0.25*G23*H23)))))) | J23: =IF(I23="N/A","不适用",IF(I23=1,"符合",IF(I23=0,"不符合","部分符合"))) | K23: =IF(COUNTIF($I23:$I31,"N/A")=COUNTA($I23:$I31),"N/A",AVERAGE($I23:$I31)) | L23: =IF(K23="N/A","不适用",IF(K23=1,"符合",IF(K23=0,"不符合","部分符合"))) | M23: =(COUNTA($C23:$C31)-COUNTIF($C23:$C31,"不适用")) | N23: =IF(I23="N/A","N/A",整体测评!O$13/M$23) | O23: =IF(I23="N/A","N/A",I23*N23) | P23: =IF(I23="N/A","N/A",N23-O23)
B24: 麒麟V10服务器 | C24: 适用 | D24: × | E24: / | F24: / | G24: 1 | H24: 1 | I24: =IF(C24="不适用","N/A",IF(D24<>"√",0,IF((E24="√")*AND(F24="√"),1,IF((E24<>"√")*AND(F24="√"),0.5*G24,IF((E24="√")*AND(F24<>"√"),0.5*H24,IF((E24<>"√")*AND(F24<>"√"),0.25*G24*H24)))))) | J24: =IF(I24="N/A","不适用",IF(I24=1,"符合",IF(I24=0,"不符合","部分符合"))) | N24: =IF(I24="N/A","N/A",整体测评!O$13/M$23) | O24: =IF(I24="N/A","N/A",I24*N24) | P24: =IF(I24="N/A","N/A",N24-O24)
B25: Linux服务器 | C25: 适用 | D25: × | E25: / | F25: / | G25: 1 | H25: 1 | I25: =IF(C25="不适用","N/A",IF(D25<>"√",0,IF((E25="√")*AND(F25="√"),1,IF((E25<>"√")*AND(F25="√"),0.5*G25,IF((E25="√")*AND(F25<>"√"),0.5*H25,IF((E25<>"√")*AND(F25<>"√"),0.25*G25*H25)))))) | J25: =IF(I25="N/A","不适用",IF(I25=1,"符合",IF(I25=0,"不符合","部分符合"))) | N25: =IF(I25="N/A","N/A",整体测评!O$13/M$23) | O25: =IF(I25="N/A","N/A",I25*N25) | P25: =IF(I25="N/A","N/A",N25-O25)
B26: Oracle数据库 | C26: 适用 | D26: × | E26: / | F26: / | G26: 1 | H26: 1 | I26: =IF(C26="不适用","N/A",IF(D26<>"√",0,IF((E26="√")*AND(F26="√"),1,IF((E26<>"√")*AND(F26="√"),0.5*G26,IF((E26="√")*AND(F26<>"√"),0.5*H26,IF((E26<>"√")*AND(F26<>"√"),0.25*G26*H26)))))) | J26: =IF(I26="N/A","不适用",IF(I26=1,"符合",IF(I26=0,"不符合","部分符合"))) | N26: =IF(I26="N/A","N/A",整体测评!O$13/M$23) | O26: =IF(I26="N/A","N/A",I26*N26) | P26: =IF(I26="N/A","N/A",N26-O26)
B27: 签名验签服务器 | C27: 适用 | D27: √ | E27: √ | F27: √ | G27: 1 | H27: 1 | I27: =IF(C27="不适用","N/A",IF(D27<>"√",0,IF((E27="√")*AND(F27="√"),1,IF((E27<>"√")*AND(F27="√"),0.5*G27,IF((E27="√")*AND(F27<>"√"),0.5*H27,IF((E27<>"√")*AND(F27<>"√"),0.25*G27*H27)))))) | J27: =IF(I27="N/A","不适用",IF(I27=1,"符合",IF(I27=0,"不符合","部分符合"))) | N27: =IF(I27="N/A","N/A",整体测评!O$13/M$23) | O27: =IF(I27="N/A","N/A",I27*N27) | P27: =IF(I27="N/A","N/A",N27-O27)
B28: 服务器密码机 | C28: 适用 | D28: √ | E28: √ | F28: √ | G28: 1 | H28: 1 | I28: =IF(C28="不适用","N/A",IF(D28<>"√",0,IF((E28="√")*AND(F28="√"),1,IF((E28<>"√")*AND(F28="√"),0.5*G28,IF((E28="√")*AND(F28<>"√"),0.5*H28,IF((E28<>"√")*AND(F28<>"√"),0.25*G28*H28)))))) | J28: =IF(I28="N/A","不适用",IF(I28=1,"符合",IF(I28=0,"不符合","部分符合"))) | N28: =IF(I28="N/A","N/A",整体测评!O$13/M$23) | O28: =IF(I28="N/A","N/A",I28*N28) | P28: =IF(I28="N/A","N/A",N28-O28)
B29: TDSQL数据库 | C29: 适用 | D29: × | E29: / | F29: / | G29: 1 | H29: 1 | I29: =IF(C29="不适用","N/A",IF(D29<>"√",0,IF((E29="√")*AND(F29="√"),1,IF((E29<>"√")*AND(F29="√"),0.5*G29,IF((E29="√")*AND(F29<>"√"),0.5*H29,IF((E29<>"√")*AND(F29<>"√"),0.25*G29*H29)))))) | J29: =IF(I29="N/A","不适用",IF(I29=1,"符合",IF(I29=0,"不符合","部分符合"))) | N29: =IF(I29="N/A","N/A",整体测评!O$13/M$23) | O29: =IF(I29="N/A","N/A",I29*N29) | P29: =IF(I29="N/A","N/A",N29-O29)
B30: SOM安全运维管理平台 | C30: 适用 | D30: × | E30: / | F30: / | G30: 1 | H30: 1 | I30: =IF(C30="不适用","N/A",IF(D30<>"√",0,IF((E30="√")*AND(F30="√"),1,IF((E30<>"√")*AND(F30="√"),0.5*G30,IF((E30="√")*AND(F30<>"√"),0.5*H30,IF((E30<>"√")*AND(F30<>"√"),0.25*G30*H30)))))) | J30: =IF(I30="N/A","不适用",IF(I30=1,"符合",IF(I30=0,"不符合","部分符合"))) | N30: =IF(I30="N/A","N/A",整体测评!O$13/M$23) | O30: =IF(I30="N/A","N/A",I30*N30) | P30: =IF(I30="N/A","N/A",N30-O30)
